Workbook

Sheet REKAP PENGELUARAN SPB 2026
A1: REKAPITULASI PENGELUARAN SPB
A2: UNIT PENYELENGGARA PELABUHAN KELAS III JAMPEA
A3: TAHUN 2026
A5: PELABUHAN JAMPEA
A6: NO | B6: BULAN | C6: JENIS / UKURAN KAPAL | H6: RUSAK / BATAL | I6: JUMLAH
C7: PPK. 27 | D7: PPK. 29 | E7: KLM | F7: KL | G7: PI
A8: 1 | B8: JANUARI | C8: 28 | D8: 2 | E8: 8 | F8: 0 | G8: 0 | H8: 0 | I8: =SUM(C8:H8) -> 38
A9: 2 | B9: FEBRUARI | C9: 37 | D9: 6 | E9: 12 | F9: 0 | G9: 0 | H9: 0 | I9: =SUM(C9:H9) -> 55
A10: 3 | B10: MARET | F10: 0 | G10: 0 | H10: 0 | I10: =SUM(C10:H10) -> 0
A11: 4 | B11: APRIL | F11: 0 | G11: 0 | H11: 0 | I11: =SUM(C11:H11) -> 0
A12: 5 | B12: MEI | F12: 0 | G12: 0 | H12: 0 | I12: =SUM(C12:H12) -> 0
A13: 6 | B13: JUNI | F13: 0 | G13: 0 | H13: 0 | I13: =SUM(C13:H13) -> 0
A14: 7 | B14: JULI | F14: 0 | G14: 0 | H14: 0 | I14: =SUM(C14:H14) -> 0
A15: 8 | B15: AGUSTUS | F15: 0 | G15: 0 | H15: 0 | I15: =SUM(C15:H15) -> 0
A16: 9 | B16: SEPTEMBER | F16: 0 | G16: 0 | H16: 0 | I16: =SUM(C16:H16) -> 0
A17: 10 | B17: OKTOBER | F17: 0 | G17: 0 | H17: 0 | I17: =SUM(C17:H17) -> 0
A18: 11 | B18: NOVEMBER | F18: 0 | G18: 0 | H18: 0 | I18: =SUM(C18:H18) -> 0
A19: 12 | B19: DESEMBER | F19: 0 | G19: 0 | H19: 0 | I19: =SUM(C19:H19) -> 0
A20: TOTAL | C20: =SUM(C8:C19) -> 65 | D20: =SUM(D8:D19) -> 8 | E20: =SUM(E8:E19) -> 20 | F20: =SUM(F8:F19) -> 0 | G20: =SUM(G8:G19) -> 0 | H20: =SUM(H8:H19) -> 0 | I20: =SUM(I8:I19) -> 93
A22: PELABUHAN UJUNG
A23: NO | B23: BULAN | C23: JENIS / UKURAN KAPAL | H23: RUSAK / BATAL | I23: JUMLAH
C24: PPK. 27 | D24: PPK. 29 | E24: KLM | F24: KL | G24: PI
A25: 1 | B25: JANUARI | C25: 0 | D25: 0 | E25: 1 | F25: 0 | G25: 0 | H25: 0 | I25: =SUM(C25:H25) -> 1
A26: 2 | B26: FEBRUARI | C26: 0 | D26: 0 | E26: 3 | F26: 0 | G26: 0 | H26: 0 | I26: =SUM(C26:H26) -> 3
A27: 3 | B27: MARET | C27: 0 | D27: 0 | F27: 0 | G27: 0 | H27: 0 | I27: =SUM(C27:H27) -> 0
A28: 4 | B28: APRIL | C28: 0 | D28: 0 | F28: 0 | G28: 0 | H28: 0 | I28: =SUM(C28:H28) -> 0
A29: 5 | B29: MEI | C29: 0 | D29: 0 | F29: 0 | G29: 0 | H29: 0 | I29: =SUM(C29:H29) -> 0
A30: 6 | B30: JUNI | C30: 0 | D30: 0 | F30: 0 | G30: 0 | H30: 0 | I30: =SUM(C30:H30) -> 0
A31: 7 | B31: JULI | C31: 0 | D31: 0 | F31: 0 | G31: 0 | H31: 0 | I31: =SUM(C31:H31) -> 0
A32: 8 | B32: AGUSTUS | C32: 0 | D32: 0 | F32: 0 | G32: 0 | H32: 0 | I32: =SUM(C32:H32) -> 0
A33: 9 | B33: SEPTEMBER | C33: 0 | D33: 0 | F33: 0 | G33: 0 | H33: 0 | I33: =SUM(C33:H33) -> 0
A34: 10 | B34: OKTOBER | C34: 0 | D34: 0 | F34: 0 | G34: 0 | H34: 0 | I34: =SUM(C34:H34) -> 0
A35: 11 | B35: NOVEMBER | C35: 0 | D35: 0 | F35: 0 | G35: 0 | H35: 0 | I35: =SUM(C35:H35) -> 0
A36: 12 | B36: DESEMBER | C36: 0 | D36: 0 | F36: 0 | G36: 0 | H36: 0 | I36: =SUM(C36:H36) -> 0
A37: TOTAL | C37: =SUM(C25:C36) -> 0 | D37: =SUM(D25:D36) -> 0 | E37: =SUM(E25:E36) -> 4 | F37: =SUM(F25:F36) -> 0 | G37: =SUM(G25:G36) -> 0 | H37: =SUM(H25:H36) -> 0 | I37: =SUM(I25:I36) -> 4
A39: PELABUHAN KAYUADI
A40: NO | B40: BULAN | C40: JENIS / UKURAN KAPAL | H40: RUSAK / BATAL | I40: JUMLAH
C41: PPK. 27 | D41: PPK. 29 | E41: KLM | F41: KL | G41: PI
A42: 1 | B42: JANUARI | C42: 12 | D42: 0 | E42: 3 | F42: 0 | G42: 0 | H42: 0 | I42: =SUM(C42:H42) -> 15
A43: 2 | B43: FEBRUARI | C43: 18 | D43: 0 | E43: 3 | F43: 0 | G43: 0 | H43: 0 | I43: =SUM(C43:H43) -> 21
...

Sheet PELRA
A1: PELAYARAN RAKYAT (PELRA)
A2: UNIT PENYELENGGARA PELABUHAN KELAS III JAMPEA
A3: TAHUN 2026
A5: PELABUHAN JAMPEA
A6: NO | B6: BULAN | C6: JUMLAH KAPAL | D6: ISI KOTOR | E6: BARANG ( TON / M3 ) | I6: HEWAN | K6: PENUMPANG
E7: BONGKAR | G7: MUAT
E8: CARGO | F8: CURAH | G8: CARGO | H8: CURAH | I8: TURUN | J8: NAIK | K8: TURUN | L8: NAIK | M8: LANJUTAN
A9: 1 | B9: JANUARI | C9: 10 | D9: 959 | E9: 337 | F9: 80 | G9: 42 | H9: 0 | I9: 0 | J9: 1 | K9: 0 | L9: 0 | M9: 0
A10: 2 | B10: FEBRUARI | C10: 18 | D10: 1038 | E10: 432 | F10: 80 | G10: 181 | H10: 0 | I10: 0 | J10: 29 | K10: 23 | L10: 5 | M10: 0
A11: 3 | B11: MARET | F11: 80 | H11: 0 | I11: 0 | M11: 0
A12: 4 | B12: APRIL | F12: 80 | H12: 0 | I12: 0 | M12: 0
A13: 5 | B13: MEI | F13: 80 | H13: 0 | I13: 0 | M13: 0
A14: 6 | B14: JUNI | F14: 80 | H14: 0 | I14: 0 | M14: 0
A15: 7 | B15: JULI | F15: 80 | H15: 0 | I15: 0 | M15: 0
A16: 8 | B16: AGUSTUS | F16: 80 | H16: 0 | I16: 0 | M16: 0
A17: 9 | B17: SEPTEMBER | F17: 80 | H17: 0 | I17: 0 | M17: 0
A18: 10 | B18: OKTOBER | F18: 80 | H18: 0 | I18: 0 | M18: 0
A19: 11 | B19: NOVEMBER | F19: 80 | H19: 0 | I19: 0 | M19: 0
A20: 12 | B20: DESEMBER | F20: 80 | H20: 0 | I20: 0 | M20: 0
A21: TOTAL | C21: =SUM(C9:C20) -> 28 | D21: =SUM(D9:D20) -> 1997 | E21: =SUM(E9:E20) -> 769 | F21: =SUM(F9:F20) -> 960 | G21: =SUM(G9:G20) -> 223 | H21: =SUM(H9:H20) -> 0 | I21: =SUM(I9:I20) -> 0 | J21: =SUM(J9:J20) -> 30 | ... M21: =SUM(M9:M20) -> 0
A23: PELABUHAN UJUNG
A24: NO | B24: BULAN | C24: JUMLAH KAPAL | D24: ISI KOTOR | E24: BARANG ( TON / M3 ) | I24: HEWAN | K24: PENUMPANG
E25: BONGKAR | G25: MUAT
E26: CARGO | F26: CURAH | G26: CARGO | H26: CURAH | I26: TURUN | J26: NAIK | K26: TURUN | L26: NAIK | M26: LANJUTAN
A27: 1 | B27: JANUARI | C27: 1 | D27: 22 | E27: 0 | F27: 0 | G27: 25 | H27: 0 | I27: 0 | J27: 0 | K27: 0 | L27: 0 | M27: 0
A28: 2 | B28: FEBRUARI | C28: 3 | D28: 59 | E28: 0 | F28: 0 | G28: 69 | H28: 0 | I28: 0 | J28: 0 | K28: 0 | L28: 0 | M28: 0
A29: 3 | B29: MARET | E29: 0 | F29: 0 | H29: 0 | I29: 0 | J29: 0 | K29: 0 | L29: 0 | M29: 0
A30: 4 | B30: APRIL | E30: 0 | F30: 0 | H30: 0 | I30: 0 | J30: 0 | K30: 0 | L30: 0 | M30: 0
A31: 5 | B31: MEI | E31: 0 | F31: 0 | H31: 0 | I31: 0 | J31: 0 | K31: 0 | L31: 0 | M31: 0
A32: 6 | B32: JUNI | E32: 0 | F32: 0 | H32: 0 | I32: 0 | J32: 0 | K32: 0 | L32: 0 | M32: 0
A33: 7 | B33: JULI | E33: 0 | F33: 0 | H33: 0 | I33: 0 | J33: 0 | K33: 0 | L33: 0 | M33: 0
A34: 8 | B34: AGUSTUS | E34: 0 | F34: 0 | H34: 0 | I34: 0 | J34: 0 | K34: 0 | L34: 0 | M34: 0
A35: 9 | B35: SEPTEMBER | E35: 0 | F35: 0 | H35: 0 | I35: 0 | J35: 0 | K35: 0 | L35: 0 | M35: 0
A36: 10 | B36: OKTOBER | E36: 0 | F36: 0 | H36: 0 | I36: 0 | J36: 0 | K36: 0 | L36: 0 | M36: 0
A37: 11 | B37: NOVEMBER | E37: 0 | F37: 0 | H37: 0 | I37: 0 | J37: 0 | K37: 0 | L37: 0 | M37: 0
A38: 12 | B38: DESEMBER | E38: 0 | F38: 0 | H38: 0 | I38: 0 | J38: 0 | K38: 0 | L38: 0 | M38: 0
A39: TOTAL | C39: =SUM(C27:C38) -> 4 | D39: =SUM(D27:D38) -> 81 | E39: =SUM(E27:E38) -> 0 | F39: =SUM(F27:F38) -> 0 | G39: =SUM(G27:G38) -> 94 | H39: =SUM(H27:H38) -> 0 | I39: =SUM(I27:I38) -> 0 | J39: =SUM(J27:J38) -> 0 | ... M39: =SUM(M27:M38) -> 0
A41: PELABUHAN KAYUADI
A42: NO | B42: BULAN | C42: JUMLAH KAPAL | D42: ISI KOTOR | E42: BARANG ( TON / M3 ) | I42: HEWAN | K42: PENUMPANG
E43: BONGKAR | G43: MUAT
...

Sheet PERINTIS
A1: PERINTIS
A2: UNIT PENYELENGGARA PELABUHAN KELAS III JAMPEA
A3: TAHUN 2026
A5: PELABUHAN JAMPEA
A6: NO | B6: BULAN | C6: JUMLAH KAPAL | D6: ISI KOTOR | E6: BARANG ( TON / M3 ) | I6: PENUMPANG | L6: MOTOR
E7: BONGKAR | G7: MUAT
E8: CARGO | F8: CURAH | G8: CARGO | H8: CURAH | I8: TURUN | J8: NAIK | K8: LANJUTAN | L8: TURUN | M8: NAIK
A9: 1 | B9: JANUARI | C9: 11 | D9: 21359 | E9: 4 | F9: 0 | G9: 1 | H9: 0 | I9: 867 | J9: 321 | K9: 679 | L9: 4 | M9: 6
A10: 2 | B10: FEBRUARI | C10: 11 | D10: 21359 | E10: 14 | F10: 0 | G10: 3 | H10: 0 | I10: 390 | J10: 275 | K10: 575 | L10: 4 | M10: 8
A11: 3 | B11: MARET | F11: 0 | H11: 0
A12: 4 | B12: APRIL | F12: 0 | H12: 0
A13: 5 | B13: MEI | F13: 0 | H13: 0
A14: 6 | B14: JUNI | F14: 0 | H14: 0
A15: 7 | B15: JULI | F15: 0 | H15: 0
A16: 8 | B16: AGUSTUS | F16: 0 | H16: 0
A17: 9 | B17: SEPTEMBER | F17: 0 | H17: 0
A18: 10 | B18: OKTOBER | F18: 0 | H18: 0
A19: 11 | B19: NOVEMBER | F19: 0 | H19: 0
A20: 12 | B20: DESEMBER | F20: 0 | H20: 0
A21: TOTAL | C21: =SUM(C9:C20) -> 22 | D21: =SUM(D9:D20) -> 42718 | E21: =SUM(E9:E20) -> 18 | F21: =SUM(F9:F20) -> 0 | G21: =SUM(G9:G20) -> 4 | H21: =SUM(H9:H20) -> 0 | I21: =SUM(I9:I20) -> 1257 | J21: =SUM(J9:J20) -> 596 | ... M21: =SUM(M9:M20) -> 14
A23: PELABUHAN UJUNG
A24: NO | B24: BULAN | C24: JUMLAH KAPAL | D24: ISI KOTOR | E24: BARANG ( TON / M3 ) | I24: PENUMPANG | L24: MOTOR
E25: BONGKAR | G25: MUAT
E26: CARGO | F26: CURAH | G26: CARGO | H26: CURAH | I26: TURUN | J26: NAIK | K26: LANJUTAN | L26: TURUN | M26: NAIK
A27: 1 | B27: JANUARI | C27: 0 | D27: 0 | E27: 0 | F27: 0 | G27: 0 | H27: 0 | I27: 0 | J27: 0 | K27: 0 | L27: 0 | M27: 0
A28: 2 | B28: FEBRUARI | C28: 0 | D28: 0 | E28: 0 | F28: 0 | G28: 0 | H28: 0 | I28: 0 | J28: 0 | K28: 0 | L28: 0 | M28: 0
A29: 3 | B29: MARET | C29: 0 | D29: 0 | E29: 0 | F29: 0 | G29: 0 | H29: 0 | I29: 0 | J29: 0 | K29: 0 | L29: 0 | M29: 0
A30: 4 | B30: APRIL | C30: 0 | D30: 0 | E30: 0 | F30: 0 | G30: 0 | H30: 0 | I30: 0 | J30: 0 | K30: 0 | L30: 0 | M30: 0
A31: 5 | B31: MEI | C31: 0 | D31: 0 | E31: 0 | F31: 0 | G31: 0 | H31: 0 | I31: 0 | J31: 0 | K31: 0 | L31: 0 | M31: 0
A32: 6 | B32: JUNI | C32: 0 | D32: 0 | E32: 0 | F32: 0 | G32: 0 | H32: 0 | I32: 0 | J32: 0 | K32: 0 | L32: 0 | M32: 0
A33: 7 | B33: JULI | C33: 0 | D33: 0 | E33: 0 | F33: 0 | G33: 0 | H33: 0 | I33: 0 | J33: 0 | K33: 0 | L33: 0 | M33: 0
A34: 8 | B34: AGUSTUS | C34: 0 | D34: 0 | E34: 0 | F34: 0 | G34: 0 | H34: 0 | I34: 0 | J34: 0 | K34: 0 | L34: 0 | M34: 0
A35: 9 | B35: SEPTEMBER | C35: 0 | D35: 0 | E35: 0 | F35: 0 | G35: 0 | H35: 0 | I35: 0 | J35: 0 | K35: 0 | L35: 0 | M35: 0
A36: 10 | B36: OKTOBER | C36: 0 | D36: 0 | E36: 0 | F36: 0 | G36: 0 | H36: 0 | I36: 0 | J36: 0 | K36: 0 | L36: 0 | M36: 0
A37: 11 | B37: NOVEMBER | C37: 0 | D37: 0 | E37: 0 | F37: 0 | G37: 0 | H37: 0 | I37: 0 | J37: 0 | K37: 0 | L37: 0 | M37: 0
A38: 12 | B38: DESEMBER | C38: 0 | D38: 0 | E38: 0 | F38: 0 | G38: 0 | H38: 0 | I38: 0 | J38: 0 | K38: 0 | L38: 0 | M38: 0
A39: TOTAL | C39: =SUM(C27:C38) -> 0 | D39: =SUM(D27:D38) -> 0 | E39: =SUM(E27:E38) -> 0 | F39: =SUM(F27:F38) -> 0 | G39: =SUM(G27:G38) -> 0 | H39: =SUM(H27:H38) -> 0 | I39: =SUM(I27:I38) -> 0 | J39: =SUM(J27:J38) -> 0 | ... M39: =SUM(M27:M38) -> 0
A41: PELABUHAN KAYUADI
A42: NO | B42: BULAN | C42: JUMLAH KAPAL | D42: ISI KOTOR | E42: BARANG ( TON / M3 ) | I42: PENUMPANG | L42: MOTOR
E43: BONGKAR | G43: MUAT
...

Sheet ANGKUTAN PENYEBRANGAN
A1: ANGKUTAN PENYEBRANGAN
A2: UNIT PENYELENGGARA PELABUHAN KELAS III JAMPEA
A3: TAHUN 2026
A5: PELABUHAN JAMPEA
A6: NO | B6: BULAN | C6: JUMLAH KAPAL | D6: ISI KOTOR | E6: KENDARAAN | I6: PENUMPANG
E7: TURUN | G7: NAIK
E8: MOBIL | F8: MOTOR | G8: MOBIL | H8: MOTOR | I8: TURUN | J8: NAIK | K8: LANJUTAN
A9: 1 | B9: JANUARI | C9: 13 | D9: 9254 | E9: 17 | F9: 102 | G9: 16 | H9: 44 | I9: 526 | J9: 199 | K9: 339
A10: 2 | B10: FEBRUARI | C10: 25 | D10: 17666 | E10: 29 | F10: 108 | G10: 25 | H10: 41 | I10: 567 | J10: 297 | K10: 484
A11: 3 | B11: MARET
A12: 4 | B12: APRIL
A13: 5 | B13: MEI
A14: 6 | B14: JUNI
A15: 7 | B15: JULI
A16: 8 | B16: AGUSTUS
A17: 9 | B17: SEPTEMBER
A18: 10 | B18: OKTOBER
A19: 11 | B19: NOVEMBER
A20: 12 | B20: DESEMBER
A21: TOTAL | C21: =SUM(C9:C20) -> 38 | D21: =SUM(D9:D20) -> 26920 | E21: =SUM(E9:E20) -> 46 | F21: =SUM(F9:F20) -> 210 | G21: =SUM(G9:G20) -> 41 | H21: =SUM(H9:H20) -> 85 | I21: =SUM(I9:I20) -> 1093 | J21: =SUM(J9:J20) -> 496 | K21: =SUM(K9:K20) -> 823
A23: PELABUHAN UJUNG
A24: NO | B24: BULAN | C24: JUMLAH KAPAL | D24: ISI KOTOR | E24: KENDARAAN | I24: PENUMPANG
E25: TURUN | G25: NAIK
E26: MOBIL | F26: MOTOR | G26: MOBIL | H26: MOTOR | I26: TURUN | J26: NAIK | K26: LANJUTAN
A27: 1 | B27: JANUARI | C27: 0 | D27: 0 | E27: 0 | F27: 0 | G27: 0 | H27: 0 | I27: 0 | J27: 0 | K27: 0
A28: 2 | B28: FEBRUARI | C28: 0 | D28: 0 | E28: 0 | F28: 0 | G28: 0 | H28: 0 | I28: 0 | J28: 0 | K28: 0
A29: 3 | B29: MARET | C29: 0 | D29: 0 | E29: 0 | F29: 0 | G29: 0 | H29: 0 | I29: 0 | J29: 0 | K29: 0
A30: 4 | B30: APRIL | C30: 0 | D30: 0 | E30: 0 | F30: 0 | G30: 0 | H30: 0 | I30: 0 | J30: 0 | K30: 0
A31: 5 | B31: MEI | C31: 0 | D31: 0 | E31: 0 | F31: 0 | G31: 0 | H31: 0 | I31: 0 | J31: 0 | K31: 0
A32: 6 | B32: JUNI | C32: 0 | D32: 0 | E32: 0 | F32: 0 | G32: 0 | H32: 0 | I32: 0 | J32: 0 | K32: 0
A33: 7 | B33: JULI | C33: 0 | D33: 0 | E33: 0 | F33: 0 | G33: 0 | H33: 0 | I33: 0 | J33: 0 | K33: 0
A34: 8 | B34: AGUSTUS | C34: 0 | D34: 0 | E34: 0 | F34: 0 | G34: 0 | H34: 0 | I34: 0 | J34: 0 | K34: 0
A35: 9 | B35: SEPTEMBER | C35: 0 | D35: 0 | E35: 0 | F35: 0 | G35: 0 | H35: 0 | I35: 0 | J35: 0 | K35: 0
A36: 10 | B36: OKTOBER | C36: 0 | D36: 0 | E36: 0 | F36: 0 | G36: 0 | H36: 0 | I36: 0 | J36: 0 | K36: 0
A37: 11 | B37: NOVEMBER | C37: 0 | D37: 0 | E37: 0 | F37: 0 | G37: 0 | H37: 0 | I37: 0 | J37: 0 | K37: 0
A38: 12 | B38: DESEMBER | C38: 0 | D38: 0 | E38: 0 | F38: 0 | G38: 0 | H38: 0 | I38: 0 | J38: 0 | K38: 0
A39: TOTAL | C39: =SUM(C27:C38) -> 0 | D39: =SUM(D27:D38) -> 0 | E39: =SUM(E27:E38) -> 0 | F39: =SUM(F27:F38) -> 0 | G39: =SUM(G27:G38) -> 0 | H39: =SUM(H27:H38) -> 0 | I39: =SUM(I27:I38) -> 0 | J39: =SUM(J27:J38) -> 0 | K39: =SUM(K27:K38) -> 0
A41: PELABUHAN KAYUADI
A42: NO | B42: BULAN | C42: JUMLAH KAPAL | D42: ISI KOTOR | E42: KENDARAAN | I42: PENUMPANG
E43: TURUN | G43: NAIK
...

Sheet ANGKUTAN LAUT DALAM NEGERI
A1: ANGKUTAN LAUT DALAM NEGERI
A2: UNIT PENYELENGGARA PELABUHAN KELAS III JAMPEA
A3: TAHUN 2026
A5: PELABUHAN JAMPEA
A6: NO | B6: BULAN | C6: JUMLAH KAPAL | D6: ISI KOTOR | E6: BARANG ( TON / M3 ) | I6: PENUMPANG
E7: BONGKAR | G7: MUAT
E8: CARGO | F8: CURAH | G8: CARGO | H8: CURAH | I8: TURUN | J8: NAIK | K8: LANJUTAN
A9: 1 | B9: JANUARI | C9: 3 | D9: 1939 | E9: 0 | F9: 0 | G9: 0 | H9: 0 | I9: 0 | J9: 0 | K9: 0
A10: 2 | B10: FEBRUARI | C10: 1 | D10: 643 | E10: 0 | F10: 0 | G10: 0 | H10: 0 | I10: 0 | J10: 0 | K10: 0
A11: 3 | B11: MARET | E11: 0 | F11: 0 | G11: 0 | H11: 0 | I11: 0 | J11: 0 | K11: 0
A12: 4 | B12: APRIL | E12: 0 | F12: 0 | G12: 0 | H12: 0 | I12: 0 | J12: 0 | K12: 0
A13: 5 | B13: MEI | E13: 0 | F13: 0 | G13: 0 | H13: 0 | I13: 0 | J13: 0 | K13: 0
A14: 6 | B14: JUNI | E14: 0 | F14: 0 | G14: 0 | H14: 0 | I14: 0 | J14: 0 | K14: 0
A15: 7 | B15: JULI | E15: 0 | F15: 0 | G15: 0 | H15: 0 | I15: 0 | J15: 0 | K15: 0
A16: 8 | B16: AGUSTUS | E16: 0 | F16: 0 | G16: 0 | H16: 0 | I16: 0 | J16: 0 | K16: 0
A17: 9 | B17: SEPTEMBER | E17: 0 | F17: 0 | G17: 0 | H17: 0 | I17: 0 | J17: 0 | K17: 0
A18: 10 | B18: OKTOBER | E18: 0 | F18: 0 | G18: 0 | H18: 0 | I18: 0 | J18: 0 | K18: 0
A19: 11 | B19: NOVEMBER | E19: 0 | F19: 0 | G19: 0 | H19: 0 | I19: 0 | J19: 0 | K19: 0
A20: 12 | B20: DESEMBER | E20: 0 | F20: 0 | G20: 0 | H20: 0 | I20: 0 | J20: 0 | K20: 0
A21: TOTAL | C21: =SUM(C9:C20) -> 4 | D21: =SUM(D9:D20) -> 2582 | E21: =SUM(E9:E20) -> 0 | F21: =SUM(F9:F20) -> 0 | G21: =SUM(G9:G20) -> 0 | H21: =SUM(H9:H20) -> 0 | I21: =SUM(I9:I20) -> 0 | J21: =SUM(J9:J20) -> 0 | K21: =SUM(K9:K20) -> 0
A23: PELABUHAN UJUNG
A24: NO | B24: BULAN | C24: JUMLAH KAPAL | D24: ISI KOTOR | E24: BARANG ( TON / M3 ) | I24: PENUMPANG
E25: BONGKAR | G25: MUAT
E26: CARGO | F26: CURAH | G26: CARGO | H26: CURAH | I26: TURUN | J26: NAIK | K26: LANJUTAN
A27: 1 | B27: JANUARI | C27: 0 | D27: 0 | E27: 0 | F27: 0 | G27: 0 | H27: 0 | I27: 0 | J27: 0 | K27: 0
A28: 2 | B28: FEBRUARI | C28: 0 | D28: 0 | E28: 0 | F28: 0 | G28: 0 | H28: 0 | I28: 0 | J28: 0 | K28: 0
A29: 3 | B29: MARET | C29: 0 | D29: 0 | E29: 0 | F29: 0 | G29: 0 | H29: 0 | I29: 0 | J29: 0 | K29: 0
A30: 4 | B30: APRIL | C30: 0 | D30: 0 | E30: 0 | F30: 0 | G30: 0 | H30: 0 | I30: 0 | J30: 0 | K30: 0
A31: 5 | B31: MEI | C31: 0 | D31: 0 | E31: 0 | F31: 0 | G31: 0 | H31: 0 | I31: 0 | J31: 0 | K31: 0
A32: 6 | B32: JUNI | C32: 0 | D32: 0 | E32: 0 | F32: 0 | G32: 0 | H32: 0 | I32: 0 | J32: 0 | K32: 0
A33: 7 | B33: JULI | C33: 0 | D33: 0 | E33: 0 | F33: 0 | G33: 0 | H33: 0 | I33: 0 | J33: 0 | K33: 0
A34: 8 | B34: AGUSTUS | C34: 0 | D34: 0 | E34: 0 | F34: 0 | G34: 0 | H34: 0 | I34: 0 | J34: 0 | K34: 0
A35: 9 | B35: SEPTEMBER | C35: 0 | D35: 0 | E35: 0 | F35: 0 | G35: 0 | H35: 0 | I35: 0 | J35: 0 | K35: 0
A36: 10 | B36: OKTOBER | C36: 0 | D36: 0 | E36: 0 | F36: 0 | G36: 0 | H36: 0 | I36: 0 | J36: 0 | K36: 0
A37: 11 | B37: NOVEMBER | C37: 0 | D37: 0 | E37: 0 | F37: 0 | G37: 0 | H37: 0 | I37: 0 | J37: 0 | K37: 0
A38: 12 | B38: DESEMBER | C38: 0 | D38: 0 | E38: 0 | F38: 0 | G38: 0 | H38: 0 | I38: 0 | J38: 0 | K38: 0
A39: TOTAL | C39: =SUM(C27:C38) -> 0 | D39: =SUM(D27:D38) -> 0 | E39: =SUM(E27:E38) -> 0 | F39: =SUM(F27:F38) -> 0 | G39: =SUM(G27:G38) -> 0 | H39: =SUM(H27:H38) -> 0 | I39: =SUM(I27:I38) -> 0 | J39: =SUM(J27:J38) -> 0 | K39: =SUM(K27:K38) -> 0
A41: PELABUHAN KAYUADI
A42: NO | B42: BULAN | C42: JUMLAH KAPAL | D42: ISI KOTOR | E42: BARANG ( TON / M3 ) | I42: PENUMPANG
E43: BONGKAR | G43: MUAT
...

Sheet ANGKUTAN LAUT LUAR NEGERI
A1: ANGKUTAN LAUT LUAR NEGERI
A2: UNIT PENYELENGGARA PELABUHAN KELAS III JAMPEA
A3: TAHUN 2026
A5: PELABUHAN JAMPEA
A6: NO | B6: BULAN | C6: JUMLAH KAPAL | D6: ISI KOTOR | E6: BARANG ( TON / M3 ) | I6: PENUMPANG
E7: BONGKAR | G7: MUAT
E8: CARGO | F8: CURAH | G8: CARGO | H8: CURAH | I8: TURUN | J8: NAIK | K8: LANJUTAN
A9: 1 | B9: JANUARI | C9: 1 | D9: 5602 | E9: 0 | F9: 0 | G9: 0 | H9: 0 | I9: 0 | J9: 0 | K9: 100
A10: 2 | B10: FEBRUARI | C10: 0 | D10: 0 | E10: 0 | F10: 0 | G10: 0 | H10: 0 | I10: 0 | J10: 0 | K10: 0
A11: 3 | B11: MARET | E11: 0 | F11: 0 | G11: 0 | H11: 0 | I11: 0 | J11: 0 | K11: 0
A12: 4 | B12: APRIL | E12: 0 | F12: 0 | G12: 0 | H12: 0 | I12: 0 | J12: 0 | K12: 0
A13: 5 | B13: MEI | E13: 0 | F13: 0 | G13: 0 | H13: 0 | I13: 0 | J13: 0 | K13: 0
A14: 6 | B14: JUNI | E14: 0 | F14: 0 | G14: 0 | H14: 0 | I14: 0 | J14: 0 | K14: 0
A15: 7 | B15: JULI | E15: 0 | F15: 0 | G15: 0 | H15: 0 | I15: 0 | J15: 0 | K15: 0
A16: 8 | B16: AGUSTUS | E16: 0 | F16: 0 | G16: 0 | H16: 0 | I16: 0 | J16: 0 | K16: 0
A17: 9 | B17: SEPTEMBER | E17: 0 | F17: 0 | G17: 0 | H17: 0 | I17: 0 | J17: 0 | K17: 0
A18: 10 | B18: OKTOBER | E18: 0 | F18: 0 | G18: 0 | H18: 0 | I18: 0 | J18: 0 | K18: 0
A19: 11 | B19: NOVEMBER | E19: 0 | F19: 0 | G19: 0 | H19: 0 | I19: 0 | J19: 0 | K19: 0
A20: 12 | B20: DESEMBER | E20: 0 | F20: 0 | G20: 0 | H20: 0 | I20: 0 | J20: 0 | K20: 0
A21: TOTAL | C21: =SUM(C9:C20) -> 1 | D21: =SUM(D9:D20) -> 5602 | E21: =SUM(E9:E20) -> 0 | F21: =SUM(F9:F20) -> 0 | G21: =SUM(G9:G20) -> 0 | H21: =SUM(H9:H20) -> 0 | I21: =SUM(I9:I20) -> 0 | J21: =SUM(J9:J20) -> 0 | K21: =SUM(K9:K20) -> 100
A23: PELABUHAN UJUNG
A24: NO | B24: BULAN | C24: JUMLAH KAPAL | D24: ISI KOTOR | E24: BARANG ( TON / M3 ) | I24: PENUMPANG
E25: BONGKAR | G25: MUAT
E26: CARGO | F26: CURAH | G26: CARGO | H26: CURAH | I26: TURUN | J26: NAIK | K26: LANJUTAN
A27: 1 | B27: JANUARI | C27: 0 | D27: 0 | E27: 0 | F27: 0 | G27: 0 | H27: 0 | I27: 0 | J27: 0 | K27: 0
A28: 2 | B28: FEBRUARI | C28: 0 | D28: 0 | E28: 0 | F28: 0 | G28: 0 | H28: 0 | I28: 0 | J28: 0 | K28: 0
A29: 3 | B29: MARET | C29: 0 | D29: 0 | E29: 0 | F29: 0 | G29: 0 | H29: 0 | I29: 0 | J29: 0 | K29: 0
A30: 4 | B30: APRIL | C30: 0 | D30: 0 | E30: 0 | F30: 0 | G30: 0 | H30: 0 | I30: 0 | J30: 0 | K30: 0
A31: 5 | B31: MEI | C31: 0 | D31: 0 | E31: 0 | F31: 0 | G31: 0 | H31: 0 | I31: 0 | J31: 0 | K31: 0
A32: 6 | B32: JUNI | C32: 0 | D32: 0 | E32: 0 | F32: 0 | G32: 0 | H32: 0 | I32: 0 | J32: 0 | K32: 0
A33: 7 | B33: JULI | C33: 0 | D33: 0 | E33: 0 | F33: 0 | G33: 0 | H33: 0 | I33: 0 | J33: 0 | K33: 0
A34: 8 | B34: AGUSTUS | C34: 0 | D34: 0 | E34: 0 | F34: 0 | G34: 0 | H34: 0 | I34: 0 | J34: 0 | K34: 0
A35: 9 | B35: SEPTEMBER | C35: 0 | D35: 0 | E35: 0 | F35: 0 | G35: 0 | H35: 0 | I35: 0 | J35: 0 | K35: 0
A36: 10 | B36: OKTOBER | C36: 0 | D36: 0 | E36: 0 | F36: 0 | G36: 0 | H36: 0 | I36: 0 | J36: 0 | K36: 0
A37: 11 | B37: NOVEMBER | C37: 0 | D37: 0 | E37: 0 | F37: 0 | G37: 0 | H37: 0 | I37: 0 | J37: 0 | K37: 0
A38: 12 | B38: DESEMBER | C38: 0 | D38: 0 | E38: 0 | F38: 0 | G38: 0 | H38: 0 | I38: 0 | J38: 0 | K38: 0
A39: TOTAL | C39: =SUM(C27:C38) -> 0 | D39: =SUM(D27:D38) -> 0 | E39: =SUM(E27:E38) -> 0 | F39: =SUM(F27:F38) -> 0 | G39: =SUM(G27:G38) -> 0 | H39: =SUM(H27:H38) -> 0 | I39: =SUM(I27:I38) -> 0 | J39: =SUM(J27:J38) -> 0 | K39: =SUM(K27:K38) -> 0
A41: PELABUHAN KAYUADI
A42: NO | B42: BULAN | C42: JUMLAH KAPAL | D42: ISI KOTOR | E42: BARANG ( TON / M3 ) | I42: PENUMPANG
E43: BONGKAR | G43: MUAT
...

Sheet REKAP LAP. OPERASIONAL 2026
A1: REKAPITULASI KEGIATAN OPERASIONAL
A2: UNIT PENYELENGGARA PELABUHAN KELAS III JAMPEA
A3: TAHUN 2026
A5: PELABUHAN JAMPEA
A6: BULAN | B6: JENIS PELAYARAN / JUMLAH KUNJUNGAN KAPAL | G6: JUMLAH | I6: BONGKAR | N6: MUAT | S6: PENUMPANG
B7: LUAR NEGERI | C7: DALAM NEGERI | D7: PELRA | E7: PERINTIS | F7: FERRY | G7: KAPAL | H7: GT. | I7: BARANG TON / M3 | K7: HEWAN EKOR | L7: KENDARAAN / UNIT | N7: BARANG TON / M3 | P7: HEWAN EKOR | Q7: KENDARAAN / UNIT | S7: TURUN | T7: NAIK | U7: LANJUTAN
I8: CARGO | J8: CURAH | L8: MOTOR | M8: MOBIL | N8: CARGO | O8: CURAH | Q8: MOTOR | R8: MOBIL | S8: ( Orang) | T8: ( Orang ) | U8: ( Orang )
A9: JANUARI | B9: =SUM('ANGKUTAN LAUT LUAR NEGERI'!C9) -> 1 | C9: =SUM('ANGKUTAN LAUT DALAM NEGERI'!C9) -> 3 | D9: =SUM(PELRA!C9) -> 10 | E9: =SUM(PERINTIS!C9) -> 11 | F9: =SUM('ANGKUTAN PENYEBRANGAN'!C9) -> 13 | G9: =SUM(B9:F9) -> 38 | H9: =SUM('ANGKUTAN LAUT LUAR NEGERI'!D9,'ANGKUTAN LAUT DALAM NEGERI'!D9,PELRA!D9,PERINTIS!D9,'ANGKUTAN PENYEBRANGAN'!D9) -> 39113 | I9: =SUM(PERINTIS!E9,PELRA!E9,'ANGKUTAN LAUT DALAM NEGERI'!E9,'ANGKUTAN LAUT LUAR NEGERI'!E9) -> 341 | J9: =SUM(PERINTIS!F9,PELRA!F9,'ANGKUTAN LAUT DALAM NEGERI'!F9,'ANGKUTAN LAUT LUAR NEGERI'!F9) -> 80 | K9: =SUM(PELRA!I9) -> 0 | L9: =SUM(PERINTIS!L9,'ANGKUTAN PENYEBRANGAN'!F9) -> 106 | M9: =SUM('ANGKUTAN PENYEBRANGAN'!E9) -> 17 | N9: =SUM(PERINTIS!G9,PELRA!G9,'ANGKUTAN LAUT DALAM NEGERI'!G9,'ANGKUTAN LAUT LUAR NEGERI'!G9) -> 43 | O9: =SUM(PERINTIS!H9,PELRA!H9,'ANGKUTAN LAUT DALAM NEGERI'!H9,'ANGKUTAN LAUT LUAR NEGERI'!H9) -> 0 | P9: =SUM(PELRA!J9) -> 1 | Q9: =SUM(PERINTIS!M9,'ANGKUTAN PENYEBRANGAN'!H9) -> 50 | R9: =SUM('ANGKUTAN PENYEBRANGAN'!G9) -> 16 | S9: =SUM('ANGKUTAN LAUT LUAR NEGERI'!I9,'ANGKUTAN LAUT DALAM NEGERI'!I9,PELRA!K9,PERINTIS!I9,'ANGKUTAN PENYEBRANGAN'!I9) -> 1393 | T9: =SUM('ANGKUTAN LAUT LUAR NEGERI'!J9,'ANGKUTAN LAUT DALAM NEGERI'!J9,PELRA!L9,PERINTIS!J9,'ANGKUTAN PENYEBRANGAN'!J9) -> 520 | U9: =SUM('ANGKUTAN LAUT LUAR NEGERI'!K9,'ANGKUTAN LAUT DALAM NEGERI'!K9,PELRA!M9,PERINTIS!K9,'ANGKUTAN PENYEBRANGAN'!K9) -> 1118
A10: FEBRUARI | B10: =SUM('ANGKUTAN LAUT LUAR NEGERI'!C10) -> 0 | C10: =SUM('ANGKUTAN LAUT DALAM NEGERI'!C10) -> 1 | D10: =SUM(PELRA!C10) -> 18 | E10: =SUM(PERINTIS!C10) -> 11 | F10: =SUM('ANGKUTAN PENYEBRANGAN'!C10) -> 25 | G10: =SUM(B10:F10) -> 55 | H10: =SUM('ANGKUTAN LAUT LUAR NEGERI'!D10,'ANGKUTAN LAUT DALAM NEGERI'!D10,PELRA!D10,PERINTIS!D10,'ANGKUTAN PENYEBRANGAN'!D10) -> 40706 | I10: =SUM(PERINTIS!E10,PELRA!E10,'ANGKUTAN LAUT DALAM NEGERI'!E10,'ANGKUTAN LAUT LUAR NEGERI'!E10) -> 446 | J10: =SUM(PERINTIS!F10,PELRA!F10,'ANGKUTAN LAUT DALAM NEGERI'!F10,'ANGKUTAN LAUT LUAR NEGERI'!F10) -> 80 | K10: =SUM(PELRA!I10) -> 0 | L10: =SUM(PERINTIS!L10,'ANGKUTAN PENYEBRANGAN'!F10) -> 112 | M10: =SUM('ANGKUTAN PENYEBRANGAN'!E10) -> 29 | N10: =SUM(PERINTIS!G10,PELRA!G10,'ANGKUTAN LAUT DALAM NEGERI'!G10,'ANGKUTAN LAUT LUAR NEGERI'!G10) -> 184 | O10: =SUM(PERINTIS!H10,PELRA!H10,'ANGKUTAN LAUT DALAM NEGERI'!H10,'ANGKUTAN LAUT LUAR NEGERI'!H10) -> 0 | P10: =SUM(PELRA!J10) -> 29 | Q10: =SUM(PERINTIS!M10,'ANGKUTAN PENYEBRANGAN'!H10) -> 49 | R10: =SUM('ANGKUTAN PENYEBRANGAN'!G10) -> 25 | S10: =SUM('ANGKUTAN LAUT LUAR NEGERI'!I10,'ANGKUTAN LAUT DALAM NEGERI'!I10,PELRA!K10,PERINTIS!I10,'ANGKUTAN PENYEBRANGAN'!I10) -> 980 | T10: =SUM('ANGKUTAN LAUT LUAR NEGERI'!J10,'ANGKUTAN LAUT DALAM NEGERI'!J10,PELRA!L10,PERINTIS!J10,'ANGKUTAN PENYEBRANGAN'!J10) -> 577 | U10: =SUM('ANGKUTAN LAUT LUAR NEGERI'!K10,'ANGKUTAN LAUT DALAM NEGERI'!K10,PELRA!M10,PERINTIS!K10,'ANGKUTAN PENYEBRANGAN'!K10) -> 1059
A11: MARET | B11: =SUM('ANGKUTAN LAUT LUAR NEGERI'!C11) -> 0 | C11: =SUM('ANGKUTAN LAUT DALAM NEGERI'!C11) -> 0 | D11: =SUM(PELRA!C11) -> 0 | E11: =SUM(PERINTIS!C11) -> 0 | F11: =SUM('ANGKUTAN PENYEBRANGAN'!C11) -> 0 | G11: =SUM(B11:F11) -> 0 | H11: =SUM('ANGKUTAN LAUT LUAR NEGERI'!D11,'ANGKUTAN LAUT DALAM NEGERI'!D11,PELRA!D11,PERINTIS!D11,'ANGKUTAN PENYEBRANGAN'!D11) -> 0 | I11: =SUM(PERINTIS!E11,PELRA!E11,'ANGKUTAN LAUT DALAM NEGERI'!E11,'ANGKUTAN LAUT LUAR NEGERI'!E11) -> 0 | J11: =SUM(PERINTIS!F11,PELRA!F11,'ANGKUTAN LAUT DALAM NEGERI'!F11,'ANGKUTAN LAUT LUAR NEGERI'!F11) -> 80 | K11: =SUM(PELRA!I11) -> 0 | L11: =SUM(PERINTIS!L11,'ANGKUTAN PENYEBRANGAN'!F11) -> 0 | M11: =SUM('ANGKUTAN PENYEBRANGAN'!E11) -> 0 | N11: =SUM(PERINTIS!G11,PELRA!G11,'ANGKUTAN LAUT DALAM NEGERI'!G11,'ANGKUTAN LAUT LUAR NEGERI'!G11) -> 0 | O11: =SUM(PERINTIS!H11,PELRA!H11,'ANGKUTAN LAUT DALAM NEGERI'!H11,'ANGKUTAN LAUT LUAR NEGERI'!H11) -> 0 | P11: =SUM(PELRA!J11) -> 0 | Q11: =SUM(PERINTIS!M11,'ANGKUTAN PENYEBRANGAN'!H11) -> 0 | R11: =SUM('ANGKUTAN PENYEBRANGAN'!G11) -> 0 | S11: =SUM('ANGKUTAN LAUT LUAR NEGERI'!I11,'ANGKUTAN LAUT DALAM NEGERI'!I11,PELRA!K11,PERINTIS!I11,'ANGKUTAN PENYEBRANGAN'!I11) -> 0 | T11: =SUM('ANGKUTAN LAUT LUAR NEGERI'!J11,'ANGKUTAN LAUT DALAM NEGERI'!J11,PELRA!L11,PERINTIS!J11,'ANGKUTAN PENYEBRANGAN'!J11) -> 0 | U11: =SUM('ANGKUTAN LAUT LUAR NEGERI'!K11,'ANGKUTAN LAUT DALAM NEGERI'!K11,PELRA!M11,PERINTIS!K11,'ANGKUTAN PENYEBRANGAN'!K11) -> 0
A12: APRIL | B12: =SUM('ANGKUTAN LAUT LUAR NEGERI'!C12) -> 0 | C12: =SUM('ANGKUTAN LAUT DALAM NEGERI'!C12) -> 0 | D12: =SUM(PELRA!C12) -> 0 | E12: =SUM(PERINTIS!C12) -> 0 | F12: =SUM('ANGKUTAN PENYEBRANGAN'!C12) -> 0 | G12: =SUM(B12:F12) -> 0 | H12: =SUM('ANGKUTAN LAUT LUAR NEGERI'!D12,'ANGKUTAN LAUT DALAM NEGERI'!D12,PELRA!D12,PERINTIS!D12,'ANGKUTAN PENYEBRANGAN'!D12) -> 0 | I12: =SUM(PERINTIS!E12,PELRA!E12,'ANGKUTAN LAUT DALAM NEGERI'!E12,'ANGKUTAN LAUT LUAR NEGERI'!E12) -> 0 | J12: =SUM(PERINTIS!F12,PELRA!F12,'ANGKUTAN LAUT DALAM NEGERI'!F12,'ANGKUTAN LAUT LUAR NEGERI'!F12) -> 80 | K12: =SUM(PELRA!I12) -> 0 | L12: =SUM(PERINTIS!L12,'ANGKUTAN PENYEBRANGAN'!F12) -> 0 | M12: =SUM('ANGKUTAN PENYEBRANGAN'!E12) -> 0 | N12: =SUM(PERINTIS!G12,PELRA!G12,'ANGKUTAN LAUT DALAM NEGERI'!G12,'ANGKUTAN LAUT LUAR NEGERI'!G12) -> 0 | O12: =SUM(PERINTIS!H12,PELRA!H12,'ANGKUTAN LAUT DALAM NEGERI'!H12,'ANGKUTAN LAUT LUAR NEGERI'!H12) -> 0 | P12: =SUM(PELRA!J12) -> 0 | Q12: =SUM(PERINTIS!M12,'ANGKUTAN PENYEBRANGAN'!H12) -> 0 | R12: =SUM('ANGKUTAN PENYEBRANGAN'!G12) -> 0 | S12: =SUM('ANGKUTAN LAUT LUAR NEGERI'!I12,'ANGKUTAN LAUT DALAM NEGERI'!I12,PELRA!K12,PERINTIS!I12,'ANGKUTAN PENYEBRANGAN'!I12) -> 0 | T12: =SUM('ANGKUTAN LAUT LUAR NEGERI'!J12,'ANGKUTAN LAUT DALAM NEGERI'!J12,PELRA!L12,PERINTIS!J12,'ANGKUTAN PENYEBRANGAN'!J12) -> 0 | U12: =SUM('ANGKUTAN LAUT LUAR NEGERI'!K12,'ANGKUTAN LAUT DALAM NEGERI'!K12,PELRA!M12,PERINTIS!K12,'ANGKUTAN PENYEBRANGAN'!K12) -> 0
A13: MEI | B13: =SUM('ANGKUTAN LAUT LUAR NEGERI'!C13) -> 0 | C13: =SUM('ANGKUTAN LAUT DALAM NEGERI'!C13) -> 0 | D13: =SUM(PELRA!C13) -> 0 | E13: =SUM(PERINTIS!C13) -> 0 | F13: =SUM('ANGKUTAN PENYEBRANGAN'!C13) -> 0 | G13: =SUM(B13:F13) -> 0 | H13: =SUM('ANGKUTAN LAUT LUAR NEGERI'!D13,'ANGKUTAN LAUT DALAM NEGERI'!D13,PELRA!D13,PERINTIS!D13,'ANGKUTAN PENYEBRANGAN'!D13) -> 0 | I13: =SUM(PERINTIS!E13,PELRA!E13,'ANGKUTAN LAUT DALAM NEGERI'!E13,'ANGKUTAN LAUT LUAR NEGERI'!E13) -> 0 | J13: =SUM(PERINTIS!F13,PELRA!F13,'ANGKUTAN LAUT DALAM NEGERI'!F13,'ANGKUTAN LAUT LUAR NEGERI'!F13) -> 80 | K13: =SUM(PELRA!I13) -> 0 | L13: =SUM(PERINTIS!L13,'ANGKUTAN PENYEBRANGAN'!F13) -> 0 | M13: =SUM('ANGKUTAN PENYEBRANGAN'!E13) -> 0 | N13: =SUM(PERINTIS!G13,PELRA!G13,'ANGKUTAN LAUT DALAM NEGERI'!G13,'ANGKUTAN LAUT LUAR NEGERI'!G13) -> 0 | O13: =SUM(PERINTIS!H13,PELRA!H13,'ANGKUTAN LAUT DALAM NEGERI'!H13,'ANGKUTAN LAUT LUAR NEGERI'!H13) -> 0 | P13: =SUM(PELRA!J13) -> 0 | Q13: =SUM(PERINTIS!M13,'ANGKUTAN PENYEBRANGAN'!H13) -> 0 | R13: =SUM('ANGKUTAN PENYEBRANGAN'!G13) -> 0 | S13: =SUM('ANGKUTAN LAUT LUAR NEGERI'!I13,'ANGKUTAN LAUT DALAM NEGERI'!I13,PELRA!K13,PERINTIS!I13,'ANGKUTAN PENYEBRANGAN'!I13) -> 0 | T13: =SUM('ANGKUTAN LAUT LUAR NEGERI'!J13,'ANGKUTAN LAUT DALAM NEGERI'!J13,PELRA!L13,PERINTIS!J13,'ANGKUTAN PENYEBRANGAN'!J13) -> 0 | U13: =SUM('ANGKUTAN LAUT LUAR NEGERI'!K13,'ANGKUTAN LAUT DALAM NEGERI'!K13,PELRA!M13,PERINTIS!K13,'ANGKUTAN PENYEBRANGAN'!K13) -> 0
A14: JUNI | B14: =SUM('ANGKUTAN LAUT LUAR NEGERI'!C14) -> 0 | C14: =SUM('ANGKUTAN LAUT DALAM NEGERI'!C14) -> 0 | D14: =SUM(PELRA!C14) -> 0 | E14: =SUM(PERINTIS!C14) -> 0 | F14: =SUM('ANGKUTAN PENYEBRANGAN'!C14) -> 0 | G14: =SUM(B14:F14) -> 0 | H14: =SUM('ANGKUTAN LAUT LUAR NEGERI'!D14,'ANGKUTAN LAUT DALAM NEGERI'!D14,PELRA!D14,PERINTIS!D14,'ANGKUTAN PENYEBRANGAN'!D14) -> 0 | I14: =SUM(PERINTIS!E14,PELRA!E14,'ANGKUTAN LAUT DALAM NEGERI'!E14,'ANGKUTAN LAUT LUAR NEGERI'!E14) -> 0 | J14: =SUM(PERINTIS!F14,PELRA!F14,'ANGKUTAN LAUT DALAM NEGERI'!F14,'ANGKUTAN LAUT LUAR NEGERI'!F14) -> 80 | K14: =SUM(PELRA!I14) -> 0 | L14: =SUM(PERINTIS!L14,'ANGKUTAN PENYEBRANGAN'!F14) -> 0 | M14: =SUM('ANGKUTAN PENYEBRANGAN'!E14) -> 0 | N14: =SUM(PERINTIS!G14,PELRA!G14,'ANGKUTAN LAUT DALAM NEGERI'!G14,'ANGKUTAN LAUT LUAR NEGERI'!G14) -> 0 | O14: =SUM(PERINTIS!H14,PELRA!H14,'ANGKUTAN LAUT DALAM NEGERI'!H14,'ANGKUTAN LAUT LUAR NEGERI'!H14) -> 0 | P14: =SUM(PELRA!J14) -> 0 | Q14: =SUM(PERINTIS!M14,'ANGKUTAN PENYEBRANGAN'!H14) -> 0 | R14: =SUM('ANGKUTAN PENYEBRANGAN'!G14) -> 0 | S14: =SUM('ANGKUTAN LAUT LUAR NEGERI'!I14,'ANGKUTAN LAUT DALAM NEGERI'!I14,PELRA!K14,PERINTIS!I14,'ANGKUTAN PENYEBRANGAN'!I14) -> 0 | T14: =SUM('ANGKUTAN LAUT LUAR NEGERI'!J14,'ANGKUTAN LAUT DALAM NEGERI'!J14,PELRA!L14,PERINTIS!J14,'ANGKUTAN PENYEBRANGAN'!J14) -> 0 | U14: =SUM('ANGKUTAN LAUT LUAR NEGERI'!K14,'ANGKUTAN LAUT DALAM NEGERI'!K14,PELRA!M14,PERINTIS!K14,'ANGKUTAN PENYEBRANGAN'!K14) -> 0
A15: JULI | B15: =SUM('ANGKUTAN LAUT LUAR NEGERI'!C15) -> 0 | C15: =SUM('ANGKUTAN LAUT DALAM NEGERI'!C15) -> 0 | D15: =SUM(PELRA!C15) -> 0 | E15: =SUM(PERINTIS!C15) -> 0 | F15: =SUM('ANGKUTAN PENYEBRANGAN'!C15) -> 0 | G15: =SUM(B15:F15) -> 0 | H15: =SUM('ANGKUTAN LAUT LUAR NEGERI'!D15,'ANGKUTAN LAUT DALAM NEGERI'!D15,PELRA!D15,PERINTIS!D15,'ANGKUTAN PENYEBRANGAN'!D15) -> 0 | I15: =SUM(PERINTIS!E15,PELRA!E15,'ANGKUTAN LAUT DALAM NEGERI'!E15,'ANGKUTAN LAUT LUAR NEGERI'!E15) -> 0 | J15: =SUM(PERINTIS!F15,PELRA!F15,'ANGKUTAN LAUT DALAM NEGERI'!F15,'ANGKUTAN LAUT LUAR NEGERI'!F15) -> 80 | K15: =SUM(PELRA!I15) -> 0 | L15: =SUM(PERINTIS!L15,'ANGKUTAN PENYEBRANGAN'!F15) -> 0 | M15: =SUM('ANGKUTAN PENYEBRANGAN'!E15) -> 0 | N15: =SUM(PERINTIS!G15,PELRA!G15,'ANGKUTAN LAUT DALAM NEGERI'!G15,'ANGKUTAN LAUT LUAR NEGERI'!G15) -> 0 | O15: =SUM(PERINTIS!H15,PELRA!H15,'ANGKUTAN LAUT DALAM NEGERI'!H15,'ANGKUTAN LAUT LUAR NEGERI'!H15) -> 0 | P15: =SUM(PELRA!J15) -> 0 | Q15: =SUM(PERINTIS!M15,'ANGKUTAN PENYEBRANGAN'!H15) -> 0 | R15: =SUM('ANGKUTAN PENYEBRANGAN'!G15) -> 0 | S15: =SUM('ANGKUTAN LAUT LUAR NEGERI'!I15,'ANGKUTAN LAUT DALAM NEGERI'!I15,PELRA!K15,PERINTIS!I15,'ANGKUTAN PENYEBRANGAN'!I15) -> 0 | T15: =SUM('ANGKUTAN LAUT LUAR NEGERI'!J15,'ANGKUTAN LAUT DALAM NEGERI'!J15,PELRA!L15,PERINTIS!J15,'ANGKUTAN PENYEBRANGAN'!J15) -> 0 | U15: =SUM('ANGKUTAN LAUT LUAR NEGERI'!K15,'ANGKUTAN LAUT DALAM NEGERI'!K15,PELRA!M15,PERINTIS!K15,'ANGKUTAN PENYEBRANGAN'!K15) -> 0
A16: AGUSTUS | B16: =SUM('ANGKUTAN LAUT LUAR NEGERI'!C16) -> 0 | C16: =SUM('ANGKUTAN LAUT DALAM NEGERI'!C16) -> 0 | D16: =SUM(PELRA!C16) -> 0 | E16: =SUM(PERINTIS!C16) -> 0 | F16: =SUM('ANGKUTAN PENYEBRANGAN'!C16) -> 0 | G16: =SUM(B16:F16) -> 0 | H16: =SUM('ANGKUTAN LAUT LUAR NEGERI'!D16,'ANGKUTAN LAUT DALAM NEGERI'!D16,PELRA!D16,PERINTIS!D16,'ANGKUTAN PENYEBRANGAN'!D16) -> 0 | I16: =SUM(PERINTIS!E16,PELRA!E16,'ANGKUTAN LAUT DALAM NEGERI'!E16,'ANGKUTAN LAUT LUAR NEGERI'!E16) -> 0 | J16: =SUM(PERINTIS!F16,PELRA!F16,'ANGKUTAN LAUT DALAM NEGERI'!F16,'ANGKUTAN LAUT LUAR NEGERI'!F16) -> 80 | K16: =SUM(PELRA!I16) -> 0 | L16: =SUM(PERINTIS!L16,'ANGKUTAN PENYEBRANGAN'!F16) -> 0 | M16: =SUM('ANGKUTAN PENYEBRANGAN'!E16) -> 0 | N16: =SUM(PERINTIS!G16,PELRA!G16,'ANGKUTAN LAUT DALAM NEGERI'!G16,'ANGKUTAN LAUT LUAR NEGERI'!G16) -> 0 | O16: =SUM(PERINTIS!H16,PELRA!H16,'ANGKUTAN LAUT DALAM NEGERI'!H16,'ANGKUTAN LAUT LUAR NEGERI'!H16) -> 0 | P16: =SUM(PELRA!J16) -> 0 | Q16: =SUM(PERINTIS!M16,'ANGKUTAN PENYEBRANGAN'!H16) -> 0 | R16: =SUM('ANGKUTAN PENYEBRANGAN'!G16) -> 0 | S16: =SUM('ANGKUTAN LAUT LUAR NEGERI'!I16,'ANGKUTAN LAUT DALAM NEGERI'!I16,PELRA!K16,PERINTIS!I16,'ANGKUTAN PENYEBRANGAN'!I16) -> 0 | T16: =SUM('ANGKUTAN LAUT LUAR NEGERI'!J16,'ANGKUTAN LAUT DALAM NEGERI'!J16,PELRA!L16,PERINTIS!J16,'ANGKUTAN PENYEBRANGAN'!J16) -> 0 | U16: =SUM('ANGKUTAN LAUT LUAR NEGERI'!K16,'ANGKUTAN LAUT DALAM NEGERI'!K16,PELRA!M16,PERINTIS!K16,'ANGKUTAN PENYEBRANGAN'!K16) -> 0
A17: SEPTEMBER | B17: =SUM('ANGKUTAN LAUT LUAR NEGERI'!C17) -> 0 | C17: =SUM('ANGKUTAN LAUT DALAM NEGERI'!C17) -> 0 | D17: =SUM(PELRA!C17) -> 0 | E17: =SUM(PERINTIS!C17) -> 0 | F17: =SUM('ANGKUTAN PENYEBRANGAN'!C17) -> 0 | G17: =SUM(B17:F17) -> 0 | H17: =SUM('ANGKUTAN LAUT LUAR NEGERI'!D17,'ANGKUTAN LAUT DALAM NEGERI'!D17,PELRA!D17,PERINTIS!D17,'ANGKUTAN PENYEBRANGAN'!D17) -> 0 | I17: =SUM(PERINTIS!E17,PELRA!E17,'ANGKUTAN LAUT DALAM NEGERI'!E17,'ANGKUTAN LAUT LUAR NEGERI'!E17) -> 0 | J17: =SUM(PERINTIS!F17,PELRA!F17,'ANGKUTAN LAUT DALAM NEGERI'!F17,'ANGKUTAN LAUT LUAR NEGERI'!F17) -> 80 | K17: =SUM(PELRA!I17) -> 0 | L17: =SUM(PERINTIS!L17,'ANGKUTAN PENYEBRANGAN'!F17) -> 0 | M17: =SUM('ANGKUTAN PENYEBRANGAN'!E17) -> 0 | N17: =SUM(PERINTIS!G17,PELRA!G17,'ANGKUTAN LAUT DALAM NEGERI'!G17,'ANGKUTAN LAUT LUAR NEGERI'!G17) -> 0 | O17: =SUM(PERINTIS!H17,PELRA!H17,'ANGKUTAN LAUT DALAM NEGERI'!H17,'ANGKUTAN LAUT LUAR NEGERI'!H17) -> 0 | P17: =SUM(PELRA!J17) -> 0 | Q17: =SUM(PERINTIS!M17,'ANGKUTAN PENYEBRANGAN'!H17) -> 0 | R17: =SUM('ANGKUTAN PENYEBRANGAN'!G17) -> 0 | S17: =SUM('ANGKUTAN LAUT LUAR NEGERI'!I17,'ANGKUTAN LAUT DALAM NEGERI'!I17,PELRA!K17,PERINTIS!I17,'ANGKUTAN PENYEBRANGAN'!I17) -> 0 | T17: =SUM('ANGKUTAN LAUT LUAR NEGERI'!J17,'ANGKUTAN LAUT DALAM NEGERI'!J17,PELRA!L17,PERINTIS!J17,'ANGKUTAN PENYEBRANGAN'!J17) -> 0 | U17: =SUM('ANGKUTAN LAUT LUAR NEGERI'!K17,'ANGKUTAN LAUT DALAM NEGERI'!K17,PELRA!M17,PERINTIS!K17,'ANGKUTAN PENYEBRANGAN'!K17) -> 0
A18: OKTOBER | B18: =SUM('ANGKUTAN LAUT LUAR NEGERI'!C18) -> 0 | C18: =SUM('ANGKUTAN LAUT DALAM NEGERI'!C18) -> 0 | D18: =SUM(PELRA!C18) -> 0 | E18: =SUM(PERINTIS!C18) -> 0 | F18: =SUM('ANGKUTAN PENYEBRANGAN'!C18) -> 0 | G18: =SUM(B18:F18) -> 0 | H18: =SUM('ANGKUTAN LAUT LUAR NEGERI'!D18,'ANGKUTAN LAUT DALAM NEGERI'!D18,PELRA!D18,PERINTIS!D18,'ANGKUTAN PENYEBRANGAN'!D18) -> 0 | I18: =SUM(PERINTIS!E18,PELRA!E18,'ANGKUTAN LAUT DALAM NEGERI'!E18,'ANGKUTAN LAUT LUAR NEGERI'!E18) -> 0 | J18: =SUM(PERINTIS!F18,PELRA!F18,'ANGKUTAN LAUT DALAM NEGERI'!F18,'ANGKUTAN LAUT LUAR NEGERI'!F18) -> 80 | K18: =SUM(PELRA!I18) -> 0 | L18: =SUM(PERINTIS!L18,'ANGKUTAN PENYEBRANGAN'!F18) -> 0 | M18: =SUM('ANGKUTAN PENYEBRANGAN'!E18) -> 0 | N18: =SUM(PERINTIS!G18,PELRA!G18,'ANGKUTAN LAUT DALAM NEGERI'!G18,'ANGKUTAN LAUT LUAR NEGERI'!G18) -> 0 | O18: =SUM(PERINTIS!H18,PELRA!H18,'ANGKUTAN LAUT DALAM NEGERI'!H18,'ANGKUTAN LAUT LUAR NEGERI'!H18) -> 0 | P18: =SUM(PELRA!J18) -> 0 | Q18: =SUM(PERINTIS!M18,'ANGKUTAN PENYEBRANGAN'!H18) -> 0 | R18: =SUM('ANGKUTAN PENYEBRANGAN'!G18) -> 0 | S18: =SUM('ANGKUTAN LAUT LUAR NEGERI'!I18,'ANGKUTAN LAUT DALAM NEGERI'!I18,PELRA!K18,PERINTIS!I18,'ANGKUTAN PENYEBRANGAN'!I18) -> 0 | T18: =SUM('ANGKUTAN LAUT LUAR NEGERI'!J18,'ANGKUTAN LAUT DALAM NEGERI'!J18,PELRA!L18,PERINTIS!J18,'ANGKUTAN PENYEBRANGAN'!J18) -> 0 | U18: =SUM('ANGKUTAN LAUT LUAR NEGERI'!K18,'ANGKUTAN LAUT DALAM NEGERI'!K18,PELRA!M18,PERINTIS!K18,'ANGKUTAN PENYEBRANGAN'!K18) -> 0
A19: NOVEMBER | B19: =SUM('ANGKUTAN LAUT LUAR NEGERI'!C19) -> 0 | C19: =SUM('ANGKUTAN LAUT DALAM NEGERI'!C19) -> 0 | D19: =SUM(PELRA!C19) -> 0 | E19: =SUM(PERINTIS!C19) -> 0 | F19: =SUM('ANGKUTAN PENYEBRANGAN'!C19) -> 0 | G19: =SUM(B19:F19) -> 0 | H19: =SUM('ANGKUTAN LAUT LUAR NEGERI'!D19,'ANGKUTAN LAUT DALAM NEGERI'!D19,PELRA!D19,PERINTIS!D19,'ANGKUTAN PENYEBRANGAN'!D19) -> 0 | I19: =SUM(PERINTIS!E19,PELRA!E19,'ANGKUTAN LAUT DALAM NEGERI'!E19,'ANGKUTAN LAUT LUAR NEGERI'!E19) -> 0 | J19: =SUM(PERINTIS!F19,PELRA!F19,'ANGKUTAN LAUT DALAM NEGERI'!F19,'ANGKUTAN LAUT LUAR NEGERI'!F19) -> 80 | K19: =SUM(PELRA!I19) -> 0 | L19: =SUM(PERINTIS!L19,'ANGKUTAN PENYEBRANGAN'!F19) -> 0 | M19: =SUM('ANGKUTAN PENYEBRANGAN'!E19) -> 0 | N19: =SUM(PERINTIS!G19,PELRA!G19,'ANGKUTAN LAUT DALAM NEGERI'!G19,'ANGKUTAN LAUT LUAR NEGERI'!G19) -> 0 | O19: =SUM(PERINTIS!H19,PELRA!H19,'ANGKUTAN LAUT DALAM NEGERI'!H19,'ANGKUTAN LAUT LUAR NEGERI'!H19) -> 0 | P19: =SUM(PELRA!J19) -> 0 | Q19: =SUM(PERINTIS!M19,'ANGKUTAN PENYEBRANGAN'!H19) -> 0 | R19: =SUM('ANGKUTAN PENYEBRANGAN'!G19) -> 0 | S19: =SUM('ANGKUTAN LAUT LUAR NEGERI'!I19,'ANGKUTAN LAUT DALAM NEGERI'!I19,PELRA!K19,PERINTIS!I19,'ANGKUTAN PENYEBRANGAN'!I19) -> 0 | T19: =SUM('ANGKUTAN LAUT LUAR NEGERI'!J19,'ANGKUTAN LAUT DALAM NEGERI'!J19,PELRA!L19,PERINTIS!J19,'ANGKUTAN PENYEBRANGAN'!J19) -> 0 | U19: =SUM('ANGKUTAN LAUT LUAR NEGERI'!K19,'ANGKUTAN LAUT DALAM NEGERI'!K19,PELRA!M19,PERINTIS!K19,'ANGKUTAN PENYEBRANGAN'!K19) -> 0
A20: DESEMBER | B20: =SUM('ANGKUTAN LAUT LUAR NEGERI'!C20) -> 0 | C20: =SUM('ANGKUTAN LAUT DALAM NEGERI'!C20) -> 0 | D20: =SUM(PELRA!C20) -> 0 | E20: =SUM(PERINTIS!C20) -> 0 | F20: =SUM('ANGKUTAN PENYEBRANGAN'!C20) -> 0 | G20: =SUM(B20:F20) -> 0 | H20: =SUM('ANGKUTAN LAUT LUAR NEGERI'!D20,'ANGKUTAN LAUT DALAM NEGERI'!D20,PELRA!D20,PERINTIS!D20,'ANGKUTAN PENYEBRANGAN'!D20) -> 0 | I20: =SUM(PERINTIS!E20,PELRA!E20,'ANGKUTAN LAUT DALAM NEGERI'!E20,'ANGKUTAN LAUT LUAR NEGERI'!E20) -> 0 | J20: =SUM(PERINTIS!F20,PELRA!F20,'ANGKUTAN LAUT DALAM NEGERI'!F20,'ANGKUTAN LAUT LUAR NEGERI'!F20) -> 80 | K20: =SUM(PELRA!I20) -> 0 | L20: =SUM(PERINTIS!L20,'ANGKUTAN PENYEBRANGAN'!F20) -> 0 | M20: =SUM('ANGKUTAN PENYEBRANGAN'!E20) -> 0 | N20: =SUM(PERINTIS!G20,PELRA!G20,'ANGKUTAN LAUT DALAM NEGERI'!G20,'ANGKUTAN LAUT LUAR NEGERI'!G20) -> 0 | O20: =SUM(PERINTIS!H20,PELRA!H20,'ANGKUTAN LAUT DALAM NEGERI'!H20,'ANGKUTAN LAUT LUAR NEGERI'!H20) -> 0 | P20: =SUM(PELRA!J20) -> 0 | Q20: =SUM(PERINTIS!M20,'ANGKUTAN PENYEBRANGAN'!H20) -> 0 | R20: =SUM('ANGKUTAN PENYEBRANGAN'!G20) -> 0 | S20: =SUM('ANGKUTAN LAUT LUAR NEGERI'!I20,'ANGKUTAN LAUT DALAM NEGERI'!I20,PELRA!K20,PERINTIS!I20,'ANGKUTAN PENYEBRANGAN'!I20) -> 0 | T20: =SUM('ANGKUTAN LAUT LUAR NEGERI'!J20,'ANGKUTAN LAUT DALAM NEGERI'!J20,PELRA!L20,PERINTIS!J20,'ANGKUTAN PENYEBRANGAN'!J20) -> 0 | U20: =SUM('ANGKUTAN LAUT LUAR NEGERI'!K20,'ANGKUTAN LAUT DALAM NEGERI'!K20,PELRA!M20,PERINTIS!K20,'ANGKUTAN PENYEBRANGAN'!K20) -> 0
A21: TOTAL | B21: =SUM(B9:B20) -> 1 | C21: =SUM(C9:C20) -> 4 | D21: =SUM(D9:D20) -> 28 | E21: =SUM(E9:E20) -> 22 | F21: =SUM(F9:F20) -> 38 | G21: =SUM(G9:G20) -> 93 | H21: =SUM(H9:H20) -> 79819 | I21: =SUM(I9:I20) -> 787 | ... U21: =SUM(U9:U20) -> 2177
A23: PELABUHAN UJUNG
A24: BULAN | B24: JENIS PELAYARAN / JUMLAH KUNJUNGAN KAPAL | G24: JUMLAH | I24: BONGKAR | N24: MUAT | S24: PENUMPANG
B25: LUAR NEGERI | C25: DALAM NEGERI | D25: PELRA | E25: PERINTIS | F25: FERRY | G25: KAPAL | H25: GT. | I25: BARANG TON / M3 | K25: HEWAN EKOR | L25: KENDARAAN / UNIT | N25: BARANG TON / M3 | P25: HEWAN EKOR | Q25: KENDARAAN / UNIT | S25: TURUN | T25: NAIK | U25: LANJUTAN
I26: CARGO | J26: CURAH | L26: MOTOR | M26: MOBIL | N26: CARGO | O26: CURAH | Q26: MOTOR | R26: MOBIL | S26: ( Orang) | T26: ( Orang ) | U26: ( Orang )
A27: JANUARI | B27: =SUM('ANGKUTAN LAUT LUAR NEGERI'!C27) -> 0 | C27: =SUM('ANGKUTAN LAUT DALAM NEGERI'!C27) -> 0 | D27: =SUM(PELRA!C27) -> 1 | E27: =SUM(PERINTIS!C27) -> 0 | F27: =SUM('ANGKUTAN PENYEBRANGAN'!C27) -> 0 | G27: =SUM(B27:F27) -> 1 | H27: =SUM('ANGKUTAN LAUT LUAR NEGERI'!D27,'ANGKUTAN LAUT DALAM NEGERI'!D27,PELRA!D27,PERINTIS!D27,'ANGKUTAN PENYEBRANGAN'!D27) -> 22 | I27: =SUM(PERINTIS!E27,PELRA!E27,'ANGKUTAN LAUT DALAM NEGERI'!E27,'ANGKUTAN LAUT LUAR NEGERI'!E27) -> 0 | J27: =SUM(PERINTIS!F27,PELRA!F27,'ANGKUTAN LAUT DALAM NEGERI'!F27,'ANGKUTAN LAUT LUAR NEGERI'!F27) -> 0 | K27: =SUM(PELRA!I27) -> 0 | L27: =SUM(PERINTIS!L27,'ANGKUTAN PENYEBRANGAN'!F27) -> 0 | M27: =SUM('ANGKUTAN PENYEBRANGAN'!E27) -> 0 | N27: =SUM(PERINTIS!G27,PELRA!G27,'ANGKUTAN LAUT DALAM NEGERI'!G27,'ANGKUTAN LAUT LUAR NEGERI'!G27) -> 25 | O27: =SUM(PERINTIS!H27,PELRA!H27,'ANGKUTAN LAUT DALAM NEGERI'!H27,'ANGKUTAN LAUT LUAR NEGERI'!H27) -> 0 | P27: =SUM(PELRA!J27) -> 0 | Q27: =SUM(PERINTIS!M27,'ANGKUTAN PENYEBRANGAN'!H27) -> 0 | R27: =SUM('ANGKUTAN PENYEBRANGAN'!G27) -> 0 | S27: =SUM('ANGKUTAN LAUT LUAR NEGERI'!I27,'ANGKUTAN LAUT DALAM NEGERI'!I27,PELRA!K27,PERINTIS!I27,'ANGKUTAN PENYEBRANGAN'!I27) -> 0 | T27: =SUM('ANGKUTAN LAUT LUAR NEGERI'!J27,'ANGKUTAN LAUT DALAM NEGERI'!J27,PELRA!L27,PERINTIS!J27,'ANGKUTAN PENYEBRANGAN'!J27) -> 0 | U27: =SUM('ANGKUTAN LAUT LUAR NEGERI'!K27,'ANGKUTAN LAUT DALAM NEGERI'!K27,PELRA!M27,PERINTIS!K27,'ANGKUTAN PENYEBRANGAN'!K27) -> 0
A28: FEBRUARI | B28: =SUM('ANGKUTAN LAUT LUAR NEGERI'!C28) -> 0 | C28: =SUM('ANGKUTAN LAUT DALAM NEGERI'!C28) -> 0 | D28: =SUM(PELRA!C28) -> 3 | E28: =SUM(PERINTIS!C28) -> 0 | F28: =SUM('ANGKUTAN PENYEBRANGAN'!C28) -> 0 | G28: =SUM(B28:F28) -> 3 | H28: =SUM('ANGKUTAN LAUT LUAR NEGERI'!D28,'ANGKUTAN LAUT DALAM NEGERI'!D28,PELRA!D28,PERINTIS!D28,'ANGKUTAN PENYEBRANGAN'!D28) -> 59 | I28: =SUM(PERINTIS!E28,PELRA!E28,'ANGKUTAN LAUT DALAM NEGERI'!E28,'ANGKUTAN LAUT LUAR NEGERI'!E28) -> 0 | J28: =SUM(PERINTIS!F28,PELRA!F28,'ANGKUTAN LAUT DALAM NEGERI'!F28,'ANGKUTAN LAUT LUAR NEGERI'!F28) -> 0 | K28: =SUM(PELRA!I28) -> 0 | L28: =SUM(PERINTIS!L28,'ANGKUTAN PENYEBRANGAN'!F28) -> 0 | M28: =SUM('ANGKUTAN PENYEBRANGAN'!E28) -> 0 | N28: =SUM(PERINTIS!G28,PELRA!G28,'ANGKUTAN LAUT DALAM NEGERI'!G28,'ANGKUTAN LAUT LUAR NEGERI'!G28) -> 69 | O28: =SUM(PERINTIS!H28,PELRA!H28,'ANGKUTAN LAUT DALAM NEGERI'!H28,'ANGKUTAN LAUT LUAR NEGERI'!H28) -> 0 | P28: =SUM(PELRA!J28) -> 0 | Q28: =SUM(PERINTIS!M28,'ANGKUTAN PENYEBRANGAN'!H28) -> 0 | R28: =SUM('ANGKUTAN PENYEBRANGAN'!G28) -> 0 | S28: =SUM('ANGKUTAN LAUT LUAR NEGERI'!I28,'ANGKUTAN LAUT DALAM NEGERI'!I28,PELRA!K28,PERINTIS!I28,'ANGKUTAN PENYEBRANGAN'!I28) -> 0 | T28: =SUM('ANGKUTAN LAUT LUAR NEGERI'!J28,'ANGKUTAN LAUT DALAM NEGERI'!J28,PELRA!L28,PERINTIS!J28,'ANGKUTAN PENYEBRANGAN'!J28) -> 0 | U28: =SUM('ANGKUTAN LAUT LUAR NEGERI'!K28,'ANGKUTAN LAUT DALAM NEGERI'!K28,PELRA!M28,PERINTIS!K28,'ANGKUTAN PENYEBRANGAN'!K28) -> 0
A29: MARET | B29: =SUM('ANGKUTAN LAUT LUAR NEGERI'!C29) -> 0 | C29: =SUM('ANGKUTAN LAUT DALAM NEGERI'!C29) -> 0 | D29: =SUM(PELRA!C29) -> 0 | E29: =SUM(PERINTIS!C29) -> 0 | F29: =SUM('ANGKUTAN PENYEBRANGAN'!C29) -> 0 | G29: =SUM(B29:F29) -> 0 | H29: =SUM('ANGKUTAN LAUT LUAR NEGERI'!D29,'ANGKUTAN LAUT DALAM NEGERI'!D29,PELRA!D29,PERINTIS!D29,'ANGKUTAN PENYEBRANGAN'!D29) -> 0 | I29: =SUM(PERINTIS!E29,PELRA!E29,'ANGKUTAN LAUT DALAM NEGERI'!E29,'ANGKUTAN LAUT LUAR NEGERI'!E29) -> 0 | J29: =SUM(PERINTIS!F29,PELRA!F29,'ANGKUTAN LAUT DALAM NEGERI'!F29,'ANGKUTAN LAUT LUAR NEGERI'!F29) -> 0 | K29: =SUM(PELRA!I29) -> 0 | L29: =SUM(PERINTIS!L29,'ANGKUTAN PENYEBRANGAN'!F29) -> 0 | M29: =SUM('ANGKUTAN PENYEBRANGAN'!E29) -> 0 | N29: =SUM(PERINTIS!G29,PELRA!G29,'ANGKUTAN LAUT DALAM NEGERI'!G29,'ANGKUTAN LAUT LUAR NEGERI'!G29) -> 0 | O29: =SUM(PERINTIS!H29,PELRA!H29,'ANGKUTAN LAUT DALAM NEGERI'!H29,'ANGKUTAN LAUT LUAR NEGERI'!H29) -> 0 | P29: =SUM(PELRA!J29) -> 0 | Q29: =SUM(PERINTIS!M29,'ANGKUTAN PENYEBRANGAN'!H29) -> 0 | R29: =SUM('ANGKUTAN PENYEBRANGAN'!G29) -> 0 | S29: =SUM('ANGKUTAN LAUT LUAR NEGERI'!I29,'ANGKUTAN LAUT DALAM NEGERI'!I29,PELRA!K29,PERINTIS!I29,'ANGKUTAN PENYEBRANGAN'!I29) -> 0 | T29: =SUM('ANGKUTAN LAUT LUAR NEGERI'!J29,'ANGKUTAN LAUT DALAM NEGERI'!J29,PELRA!L29,PERINTIS!J29,'ANGKUTAN PENYEBRANGAN'!J29) -> 0 | U29: =SUM('ANGKUTAN LAUT LUAR NEGERI'!K29,'ANGKUTAN LAUT DALAM NEGERI'!K29,PELRA!M29,PERINTIS!K29,'ANGKUTAN PENYEBRANGAN'!K29) -> 0
A30: APRIL | B30: =SUM('ANGKUTAN LAUT LUAR NEGERI'!C30) -> 0 | C30: =SUM('ANGKUTAN LAUT DALAM NEGERI'!C30) -> 0 | D30: =SUM(PELRA!C30) -> 0 | E30: =SUM(PERINTIS!C30) -> 0 | F30: =SUM('ANGKUTAN PENYEBRANGAN'!C30) -> 0 | G30: =SUM(B30:F30) -> 0 | H30: =SUM('ANGKUTAN LAUT LUAR NEGERI'!D30,'ANGKUTAN LAUT DALAM NEGERI'!D30,PELRA!D30,PERINTIS!D30,'ANGKUTAN PENYEBRANGAN'!D30) -> 0 | I30: =SUM(PERINTIS!E30,PELRA!E30,'ANGKUTAN LAUT DALAM NEGERI'!E30,'ANGKUTAN LAUT LUAR NEGERI'!E30) -> 0 | J30: =SUM(PERINTIS!F30,PELRA!F30,'ANGKUTAN LAUT DALAM NEGERI'!F30,'ANGKUTAN LAUT LUAR NEGERI'!F30) -> 0 | K30: =SUM(PELRA!I30) -> 0 | L30: =SUM(PERINTIS!L30,'ANGKUTAN PENYEBRANGAN'!F30) -> 0 | M30: =SUM('ANGKUTAN PENYEBRANGAN'!E30) -> 0 | N30: =SUM(PERINTIS!G30,PELRA!G30,'ANGKUTAN LAUT DALAM NEGERI'!G30,'ANGKUTAN LAUT LUAR NEGERI'!G30) -> 0 | O30: =SUM(PERINTIS!H30,PELRA!H30,'ANGKUTAN LAUT DALAM NEGERI'!H30,'ANGKUTAN LAUT LUAR NEGERI'!H30) -> 0 | P30: =SUM(PELRA!J30) -> 0 | Q30: =SUM(PERINTIS!M30,'ANGKUTAN PENYEBRANGAN'!H30) -> 0 | R30: =SUM('ANGKUTAN PENYEBRANGAN'!G30) -> 0 | S30: =SUM('ANGKUTAN LAUT LUAR NEGERI'!I30,'ANGKUTAN LAUT DALAM NEGERI'!I30,PELRA!K30,PERINTIS!I30,'ANGKUTAN PENYEBRANGAN'!I30) -> 0 | T30: =SUM('ANGKUTAN LAUT LUAR NEGERI'!J30,'ANGKUTAN LAUT DALAM NEGERI'!J30,PELRA!L30,PERINTIS!J30,'ANGKUTAN PENYEBRANGAN'!J30) -> 0 | U30: =SUM('ANGKUTAN LAUT LUAR NEGERI'!K30,'ANGKUTAN LAUT DALAM NEGERI'!K30,PELRA!M30,PERINTIS!K30,'ANGKUTAN PENYEBRANGAN'!K30) -> 0
A31: MEI | B31: =SUM('ANGKUTAN LAUT LUAR NEGERI'!C31) -> 0 | C31: =SUM('ANGKUTAN LAUT DALAM NEGERI'!C31) -> 0 | D31: =SUM(PELRA!C31) -> 0 | E31: =SUM(PERINTIS!C31) -> 0 | F31: =SUM('ANGKUTAN PENYEBRANGAN'!C31) -> 0 | G31: =SUM(B31:F31) -> 0 | H31: =SUM('ANGKUTAN LAUT LUAR NEGERI'!D31,'ANGKUTAN LAUT DALAM NEGERI'!D31,PELRA!D31,PERINTIS!D31,'ANGKUTAN PENYEBRANGAN'!D31) -> 0 | I31: =SUM(PERINTIS!E31,PELRA!E31,'ANGKUTAN LAUT DALAM NEGERI'!E31,'ANGKUTAN LAUT LUAR NEGERI'!E31) -> 0 | J31: =SUM(PERINTIS!F31,PELRA!F31,'ANGKUTAN LAUT DALAM NEGERI'!F31,'ANGKUTAN LAUT LUAR NEGERI'!F31) -> 0 | K31: =SUM(PELRA!I31) -> 0 | L31: =SUM(PERINTIS!L31,'ANGKUTAN PENYEBRANGAN'!F31) -> 0 | M31: =SUM('ANGKUTAN PENYEBRANGAN'!E31) -> 0 | N31: =SUM(PERINTIS!G31,PELRA!G31,'ANGKUTAN LAUT DALAM NEGERI'!G31,'ANGKUTAN LAUT LUAR NEGERI'!G31) -> 0 | O31: =SUM(PERINTIS!H31,PELRA!H31,'ANGKUTAN LAUT DALAM NEGERI'!H31,'ANGKUTAN LAUT LUAR NEGERI'!H31) -> 0 | P31: =SUM(PELRA!J31) -> 0 | Q31: =SUM(PERINTIS!M31,'ANGKUTAN PENYEBRANGAN'!H31) -> 0 | R31: =SUM('ANGKUTAN PENYEBRANGAN'!G31) -> 0 | S31: =SUM('ANGKUTAN LAUT LUAR NEGERI'!I31,'ANGKUTAN LAUT DALAM NEGERI'!I31,PELRA!K31,PERINTIS!I31,'ANGKUTAN PENYEBRANGAN'!I31) -> 0 | T31: =SUM('ANGKUTAN LAUT LUAR NEGERI'!J31,'ANGKUTAN LAUT DALAM NEGERI'!J31,PELRA!L31,PERINTIS!J31,'ANGKUTAN PENYEBRANGAN'!J31) -> 0 | U31: =SUM('ANGKUTAN LAUT LUAR NEGERI'!K31,'ANGKUTAN LAUT DALAM NEGERI'!K31,PELRA!M31,PERINTIS!K31,'ANGKUTAN PENYEBRANGAN'!K31) -> 0
A32: JUNI | B32: =SUM('ANGKUTAN LAUT LUAR NEGERI'!C32) -> 0 | C32: =SUM('ANGKUTAN LAUT DALAM NEGERI'!C32) -> 0 | D32: =SUM(PELRA!C32) -> 0 | E32: =SUM(PERINTIS!C32) -> 0 | F32: =SUM('ANGKUTAN PENYEBRANGAN'!C32) -> 0 | G32: =SUM(B32:F32) -> 0 | H32: =SUM('ANGKUTAN LAUT LUAR NEGERI'!D32,'ANGKUTAN LAUT DALAM NEGERI'!D32,PELRA!D32,PERINTIS!D32,'ANGKUTAN PENYEBRANGAN'!D32) -> 0 | I32: =SUM(PERINTIS!E32,PELRA!E32,'ANGKUTAN LAUT DALAM NEGERI'!E32,'ANGKUTAN LAUT LUAR NEGERI'!E32) -> 0 | J32: =SUM(PERINTIS!F32,PELRA!F32,'ANGKUTAN LAUT DALAM NEGERI'!F32,'ANGKUTAN LAUT LUAR NEGERI'!F32) -> 0 | K32: =SUM(PELRA!I32) -> 0 | L32: =SUM(PERINTIS!L32,'ANGKUTAN PENYEBRANGAN'!F32) -> 0 | M32: =SUM('ANGKUTAN PENYEBRANGAN'!E32) -> 0 | N32: =SUM(PERINTIS!G32,PELRA!G32,'ANGKUTAN LAUT DALAM NEGERI'!G32,'ANGKUTAN LAUT LUAR NEGERI'!G32) -> 0 | O32: =SUM(PERINTIS!H32,PELRA!H32,'ANGKUTAN LAUT DALAM NEGERI'!H32,'ANGKUTAN LAUT LUAR NEGERI'!H32) -> 0 | P32: =SUM(PELRA!J32) -> 0 | Q32: =SUM(PERINTIS!M32,'ANGKUTAN PENYEBRANGAN'!H32) -> 0 | R32: =SUM('ANGKUTAN PENYEBRANGAN'!G32) -> 0 | S32: =SUM('ANGKUTAN LAUT LUAR NEGERI'!I32,'ANGKUTAN LAUT DALAM NEGERI'!I32,PELRA!K32,PERINTIS!I32,'ANGKUTAN PENYEBRANGAN'!I32) -> 0 | T32: =SUM('ANGKUTAN LAUT LUAR NEGERI'!J32,'ANGKUTAN LAUT DALAM NEGERI'!J32,PELRA!L32,PERINTIS!J32,'ANGKUTAN PENYEBRANGAN'!J32) -> 0 | U32: =SUM('ANGKUTAN LAUT LUAR NEGERI'!K32,'ANGKUTAN LAUT DALAM NEGERI'!K32,PELRA!M32,PERINTIS!K32,'ANGKUTAN PENYEBRANGAN'!K32) -> 0
A33: JULI | B33: =SUM('ANGKUTAN LAUT LUAR NEGERI'!C33) -> 0 | C33: =SUM('ANGKUTAN LAUT DALAM NEGERI'!C33) -> 0 | D33: =SUM(PELRA!C33) -> 0 | E33: =SUM(PERINTIS!C33) -> 0 | F33: =SUM('ANGKUTAN PENYEBRANGAN'!C33) -> 0 | G33: =SUM(B33:F33) -> 0 | H33: =SUM('ANGKUTAN LAUT LUAR NEGERI'!D33,'ANGKUTAN LAUT DALAM NEGERI'!D33,PELRA!D33,PERINTIS!D33,'ANGKUTAN PENYEBRANGAN'!D33) -> 0 | I33: =SUM(PERINTIS!E33,PELRA!E33,'ANGKUTAN LAUT DALAM NEGERI'!E33,'ANGKUTAN LAUT LUAR NEGERI'!E33) -> 0 | J33: =SUM(PERINTIS!F33,PELRA!F33,'ANGKUTAN LAUT DALAM NEGERI'!F33,'ANGKUTAN LAUT LUAR NEGERI'!F33) -> 0 | K33: =SUM(PELRA!I33) -> 0 | L33: =SUM(PERINTIS!L33,'ANGKUTAN PENYEBRANGAN'!F33) -> 0 | M33: =SUM('ANGKUTAN PENYEBRANGAN'!E33) -> 0 | N33: =SUM(PERINTIS!G33,PELRA!G33,'ANGKUTAN LAUT DALAM NEGERI'!G33,'ANGKUTAN LAUT LUAR NEGERI'!G33) -> 0 | O33: =SUM(PERINTIS!H33,PELRA!H33,'ANGKUTAN LAUT DALAM NEGERI'!H33,'ANGKUTAN LAUT LUAR NEGERI'!H33) -> 0 | P33: =SUM(PELRA!J33) -> 0 | Q33: =SUM(PERINTIS!M33,'ANGKUTAN PENYEBRANGAN'!H33) -> 0 | R33: =SUM('ANGKUTAN PENYEBRANGAN'!G33) -> 0 | S33: =SUM('ANGKUTAN LAUT LUAR NEGERI'!I33,'ANGKUTAN LAUT DALAM NEGERI'!I33,PELRA!K33,PERINTIS!I33,'ANGKUTAN PENYEBRANGAN'!I33) -> 0 | T33: =SUM('ANGKUTAN LAUT LUAR NEGERI'!J33,'ANGKUTAN LAUT DALAM NEGERI'!J33,PELRA!L33,PERINTIS!J33,'ANGKUTAN PENYEBRANGAN'!J33) -> 0 | U33: =SUM('ANGKUTAN LAUT LUAR NEGERI'!K33,'ANGKUTAN LAUT DALAM NEGERI'!K33,PELRA!M33,PERINTIS!K33,'ANGKUTAN PENYEBRANGAN'!K33) -> 0
A34: AGUSTUS | B34: =SUM('ANGKUTAN LAUT LUAR NEGERI'!C34) -> 0 | C34: =SUM('ANGKUTAN LAUT DALAM NEGERI'!C34) -> 0 | D34: =SUM(PELRA!C34) -> 0 | E34: =SUM(PERINTIS!C34) -> 0 | F34: =SUM('ANGKUTAN PENYEBRANGAN'!C34) -> 0 | G34: =SUM(B34:F34) -> 0 | H34: =SUM('ANGKUTAN LAUT LUAR NEGERI'!D34,'ANGKUTAN LAUT DALAM NEGERI'!D34,PELRA!D34,PERINTIS!D34,'ANGKUTAN PENYEBRANGAN'!D34) -> 0 | I34: =SUM(PERINTIS!E34,PELRA!E34,'ANGKUTAN LAUT DALAM NEGERI'!E34,'ANGKUTAN LAUT LUAR NEGERI'!E34) -> 0 | J34: =SUM(PERINTIS!F34,PELRA!F34,'ANGKUTAN LAUT DALAM NEGERI'!F34,'ANGKUTAN LAUT LUAR NEGERI'!F34) -> 0 | K34: =SUM(PELRA!I34) -> 0 | L34: =SUM(PERINTIS!L34,'ANGKUTAN PENYEBRANGAN'!F34) -> 0 | M34: =SUM('ANGKUTAN PENYEBRANGAN'!E34) -> 0 | N34: =SUM(PERINTIS!G34,PELRA!G34,'ANGKUTAN LAUT DALAM NEGERI'!G34,'ANGKUTAN LAUT LUAR NEGERI'!G34) -> 0 | O34: =SUM(PERINTIS!H34,PELRA!H34,'ANGKUTAN LAUT DALAM NEGERI'!H34,'ANGKUTAN LAUT LUAR NEGERI'!H34) -> 0 | P34: =SUM(PELRA!J34) -> 0 | Q34: =SUM(PERINTIS!M34,'ANGKUTAN PENYEBRANGAN'!H34) -> 0 | R34: =SUM('ANGKUTAN PENYEBRANGAN'!G34) -> 0 | S34: =SUM('ANGKUTAN LAUT LUAR NEGERI'!I34,'ANGKUTAN LAUT DALAM NEGERI'!I34,PELRA!K34,PERINTIS!I34,'ANGKUTAN PENYEBRANGAN'!I34) -> 0 | T34: =SUM('ANGKUTAN LAUT LUAR NEGERI'!J34,'ANGKUTAN LAUT DALAM NEGERI'!J34,PELRA!L34,PERINTIS!J34,'ANGKUTAN PENYEBRANGAN'!J34) -> 0 | U34: =SUM('ANGKUTAN LAUT LUAR NEGERI'!K34,'ANGKUTAN LAUT DALAM NEGERI'!K34,PELRA!M34,PERINTIS!K34,'ANGKUTAN PENYEBRANGAN'!K34) -> 0
A35: SEPTEMBER | B35: =SUM('ANGKUTAN LAUT LUAR NEGERI'!C35) -> 0 | C35: =SUM('ANGKUTAN LAUT DALAM NEGERI'!C35) -> 0 | D35: =SUM(PELRA!C35) -> 0 | E35: =SUM(PERINTIS!C35) -> 0 | F35: =SUM('ANGKUTAN PENYEBRANGAN'!C35) -> 0 | G35: =SUM(B35:F35) -> 0 | H35: =SUM('ANGKUTAN LAUT LUAR NEGERI'!D35,'ANGKUTAN LAUT DALAM NEGERI'!D35,PELRA!D35,PERINTIS!D35,'ANGKUTAN PENYEBRANGAN'!D35) -> 0 | I35: =SUM(PERINTIS!E35,PELRA!E35,'ANGKUTAN LAUT DALAM NEGERI'!E35,'ANGKUTAN LAUT LUAR NEGERI'!E35) -> 0 | J35: =SUM(PERINTIS!F35,PELRA!F35,'ANGKUTAN LAUT DALAM NEGERI'!F35,'ANGKUTAN LAUT LUAR NEGERI'!F35) -> 0 | K35: =SUM(PELRA!I35) -> 0 | L35: =SUM(PERINTIS!L35,'ANGKUTAN PENYEBRANGAN'!F35) -> 0 | M35: =SUM('ANGKUTAN PENYEBRANGAN'!E35) -> 0 | N35: =SUM(PERINTIS!G35,PELRA!G35,'ANGKUTAN LAUT DALAM NEGERI'!G35,'ANGKUTAN LAUT LUAR NEGERI'!G35) -> 0 | O35: =SUM(PERINTIS!H35,PELRA!H35,'ANGKUTAN LAUT DALAM NEGERI'!H35,'ANGKUTAN LAUT LUAR NEGERI'!H35) -> 0 | P35: =SUM(PELRA!J35) -> 0 | Q35: =SUM(PERINTIS!M35,'ANGKUTAN PENYEBRANGAN'!H35) -> 0 | R35: =SUM('ANGKUTAN PENYEBRANGAN'!G35) -> 0 | S35: =SUM('ANGKUTAN LAUT LUAR NEGERI'!I35,'ANGKUTAN LAUT DALAM NEGERI'!I35,PELRA!K35,PERINTIS!I35,'ANGKUTAN PENYEBRANGAN'!I35) -> 0 | T35: =SUM('ANGKUTAN LAUT LUAR NEGERI'!J35,'ANGKUTAN LAUT DALAM NEGERI'!J35,PELRA!L35,PERINTIS!J35,'ANGKUTAN PENYEBRANGAN'!J35) -> 0 | U35: =SUM('ANGKUTAN LAUT LUAR NEGERI'!K35,'ANGKUTAN LAUT DALAM NEGERI'!K35,PELRA!M35,PERINTIS!K35,'ANGKUTAN PENYEBRANGAN'!K35) -> 0
A36: OKTOBER | B36: =SUM('ANGKUTAN LAUT LUAR NEGERI'!C36) -> 0 | C36: =SUM('ANGKUTAN LAUT DALAM NEGERI'!C36) -> 0 | D36: =SUM(PELRA!C36) -> 0 | E36: =SUM(PERINTIS!C36) -> 0 | F36: =SUM('ANGKUTAN PENYEBRANGAN'!C36) -> 0 | G36: =SUM(B36:F36) -> 0 | H36: =SUM('ANGKUTAN LAUT LUAR NEGERI'!D36,'ANGKUTAN LAUT DALAM NEGERI'!D36,PELRA!D36,PERINTIS!D36,'ANGKUTAN PENYEBRANGAN'!D36) -> 0 | I36: =SUM(PERINTIS!E36,PELRA!E36,'ANGKUTAN LAUT DALAM NEGERI'!E36,'ANGKUTAN LAUT LUAR NEGERI'!E36) -> 0 | J36: =SUM(PERINTIS!F36,PELRA!F36,'ANGKUTAN LAUT DALAM NEGERI'!F36,'ANGKUTAN LAUT LUAR NEGERI'!F36) -> 0 | K36: =SUM(PELRA!I36) -> 0 | L36: =SUM(PERINTIS!L36,'ANGKUTAN PENYEBRANGAN'!F36) -> 0 | M36: =SUM('ANGKUTAN PENYEBRANGAN'!E36) -> 0 | N36: =SUM(PERINTIS!G36,PELRA!G36,'ANGKUTAN LAUT DALAM NEGERI'!G36,'ANGKUTAN LAUT LUAR NEGERI'!G36) -> 0 | O36: =SUM(PERINTIS!H36,PELRA!H36,'ANGKUTAN LAUT DALAM NEGERI'!H36,'ANGKUTAN LAUT LUAR NEGERI'!H36) -> 0 | P36: =SUM(PELRA!J36) -> 0 | Q36: =SUM(PERINTIS!M36,'ANGKUTAN PENYEBRANGAN'!H36) -> 0 | R36: =SUM('ANGKUTAN PENYEBRANGAN'!G36) -> 0 | S36: =SUM('ANGKUTAN LAUT LUAR NEGERI'!I36,'ANGKUTAN LAUT DALAM NEGERI'!I36,PELRA!K36,PERINTIS!I36,'ANGKUTAN PENYEBRANGAN'!I36) -> 0 | T36: =SUM('ANGKUTAN LAUT LUAR NEGERI'!J36,'ANGKUTAN LAUT DALAM NEGERI'!J36,PELRA!L36,PERINTIS!J36,'ANGKUTAN PENYEBRANGAN'!J36) -> 0 | U36: =SUM('ANGKUTAN LAUT LUAR NEGERI'!K36,'ANGKUTAN LAUT DALAM NEGERI'!K36,PELRA!M36,PERINTIS!K36,'ANGKUTAN PENYEBRANGAN'!K36) -> 0
A37: NOVEMBER | B37: =SUM('ANGKUTAN LAUT LUAR NEGERI'!C37) -> 0 | C37: =SUM('ANGKUTAN LAUT DALAM NEGERI'!C37) -> 0 | D37: =SUM(PELRA!C37) -> 0 | E37: =SUM(PERINTIS!C37) -> 0 | F37: =SUM('ANGKUTAN PENYEBRANGAN'!C37) -> 0 | G37: =SUM(B37:F37) -> 0 | H37: =SUM('ANGKUTAN LAUT LUAR NEGERI'!D37,'ANGKUTAN LAUT DALAM NEGERI'!D37,PELRA!D37,PERINTIS!D37,'ANGKUTAN PENYEBRANGAN'!D37) -> 0 | I37: =SUM(PERINTIS!E37,PELRA!E37,'ANGKUTAN LAUT DALAM NEGERI'!E37,'ANGKUTAN LAUT LUAR NEGERI'!E37) -> 0 | J37: =SUM(PERINTIS!F37,PELRA!F37,'ANGKUTAN LAUT DALAM NEGERI'!F37,'ANGKUTAN LAUT LUAR NEGERI'!F37) -> 0 | K37: =SUM(PELRA!I37) -> 0 | L37: =SUM(PERINTIS!L37,'ANGKUTAN PENYEBRANGAN'!F37) -> 0 | M37: =SUM('ANGKUTAN PENYEBRANGAN'!E37) -> 0 | N37: =SUM(PERINTIS!G37,PELRA!G37,'ANGKUTAN LAUT DALAM NEGERI'!G37,'ANGKUTAN LAUT LUAR NEGERI'!G37) -> 0 | O37: =SUM(PERINTIS!H37,PELRA!H37,'ANGKUTAN LAUT DALAM NEGERI'!H37,'ANGKUTAN LAUT LUAR NEGERI'!H37) -> 0 | P37: =SUM(PELRA!J37) -> 0 | Q37: =SUM(PERINTIS!M37,'ANGKUTAN PENYEBRANGAN'!H37) -> 0 | R37: =SUM('ANGKUTAN PENYEBRANGAN'!G37) -> 0 | S37: =SUM('ANGKUTAN LAUT LUAR NEGERI'!I37,'ANGKUTAN LAUT DALAM NEGERI'!I37,PELRA!K37,PERINTIS!I37,'ANGKUTAN PENYEBRANGAN'!I37) -> 0 | T37: =SUM('ANGKUTAN LAUT LUAR NEGERI'!J37,'ANGKUTAN LAUT DALAM NEGERI'!J37,PELRA!L37,PERINTIS!J37,'ANGKUTAN PENYEBRANGAN'!J37) -> 0 | U37: =SUM('ANGKUTAN LAUT LUAR NEGERI'!K37,'ANGKUTAN LAUT DALAM NEGERI'!K37,PELRA!M37,PERINTIS!K37,'ANGKUTAN PENYEBRANGAN'!K37) -> 0
A38: DESEMBER | B38: =SUM('ANGKUTAN LAUT LUAR NEGERI'!C38) -> 0 | C38: =SUM('ANGKUTAN LAUT DALAM NEGERI'!C38) -> 0 | D38: =SUM(PELRA!C38) -> 0 | E38: =SUM(PERINTIS!C38) -> 0 | F38: =SUM('ANGKUTAN PENYEBRANGAN'!C38) -> 0 | G38: =SUM(B38:F38) -> 0 | H38: =SUM('ANGKUTAN LAUT LUAR NEGERI'!D38,'ANGKUTAN LAUT DALAM NEGERI'!D38,PELRA!D38,PERINTIS!D38,'ANGKUTAN PENYEBRANGAN'!D38) -> 0 | I38: =SUM(PERINTIS!E38,PELRA!E38,'ANGKUTAN LAUT DALAM NEGERI'!E38,'ANGKUTAN LAUT LUAR NEGERI'!E38) -> 0 | J38: =SUM(PERINTIS!F38,PELRA!F38,'ANGKUTAN LAUT DALAM NEGERI'!F38,'ANGKUTAN LAUT LUAR NEGERI'!F38) -> 0 | K38: =SUM(PELRA!I38) -> 0 | L38: =SUM(PERINTIS!L38,'ANGKUTAN PENYEBRANGAN'!F38) -> 0 | M38: =SUM('ANGKUTAN PENYEBRANGAN'!E38) -> 0 | N38: =SUM(PERINTIS!G38,PELRA!G38,'ANGKUTAN LAUT DALAM NEGERI'!G38,'ANGKUTAN LAUT LUAR NEGERI'!G38) -> 0 | O38: =SUM(PERINTIS!H38,PELRA!H38,'ANGKUTAN LAUT DALAM NEGERI'!H38,'ANGKUTAN LAUT LUAR NEGERI'!H38) -> 0 | P38: =SUM(PELRA!J38) -> 0 | Q38: =SUM(PERINTIS!M38,'ANGKUTAN PENYEBRANGAN'!H38) -> 0 | R38: =SUM('ANGKUTAN PENYEBRANGAN'!G38) -> 0 | S38: =SUM('ANGKUTAN LAUT LUAR NEGERI'!I38,'ANGKUTAN LAUT DALAM NEGERI'!I38,PELRA!K38,PERINTIS!I38,'ANGKUTAN PENYEBRANGAN'!I38) -> 0 | T38: =SUM('ANGKUTAN LAUT LUAR NEGERI'!J38,'ANGKUTAN LAUT DALAM NEGERI'!J38,PELRA!L38,PERINTIS!J38,'ANGKUTAN PENYEBRANGAN'!J38) -> 0 | U38: =SUM('ANGKUTAN LAUT LUAR NEGERI'!K38,'ANGKUTAN LAUT DALAM NEGERI'!K38,PELRA!M38,PERINTIS!K38,'ANGKUTAN PENYEBRANGAN'!K38) -> 0
A39: TOTAL | B39: =SUM(B27:B38) -> 0 | C39: =SUM(C27:C38) -> 0 | D39: =SUM(D27:D38) -> 4 | E39: =SUM(E27:E38) -> 0 | F39: =SUM(F27:F38) -> 0 | G39: =SUM(G27:G38) -> 4 | H39: =SUM(H27:H38) -> 81 | I39: =SUM(I27:I38) -> 0 | ... U39: =SUM(U27:U38) -> 0
A41: PELABUHAN KAYUADI
A42: BULAN | B42: JENIS PELAYARAN / JUMLAH KUNJUNGAN KAPAL | G42: JUMLAH | I42: BONGKAR | N42: MUAT | S42: PENUMPANG
B43: LUAR NEGERI | C43: DALAM NEGERI | D43: PELRA | E43: PERINTIS | F43: FERRY | G43: KAPAL | H43: GT. | I43: BARANG TON / M3 | K43: HEWAN EKOR | L43: KENDARAAN / UNIT | N43: BARANG TON / M3 | P43: HEWAN EKOR | Q43: KENDARAAN / UNIT | S43: TURUN | T43: NAIK | U43: LANJUTAN
...
